Workbook

Sheet 요약
A1: LINE Messaging API 메시지 송수신 테스트 케이스
A2: - 요구사항 22건(REQ-01~22)은 LINE Developers 공개 문서(Messaging API reference·docs, 2026-10-25 조회)에서 역도출. 질의사항 13건(Q01~Q13)은 실제 응답으로 확정하며 기대결과에 'Qn 회신 후 확정' 표기
A3: - 설계 근거: 요구사항(공개 문서에서 직접 도출) / 리스크 기반(문서 외, 중복 발송·유실·보안 영향 큼) / 추가 검증(범위 외 품질 확인)
A4: - 입력: '테스트케이스' 시트 노란 칸. 결과는 Pass/Fail/Blocked/N/A 선택. 집계는 자동 계산
A5: - 실행 구분: 무발송(사용자에게 메시지가 가지 않음) / 발송(테스트 사용자에게 실제 도달, 월 한도 소모) / 장기·한도(24시간 키 만료·14일 상태 창·시간당 한도 등 시간 경과 필요). 자동화 구분: API / UI(LINE 앱·콘솔 확인) / 수동 — 계획서 8장
A7: 대분류 | B7: TC 수 | C7: P1 | D7: P2 | E7: P3 | F7: Pass | G7: Fail | H7: Blocked | I7: 미완료
A8: 인증·토큰 | B8: =COUNTIF('테스트케이스'!$B$2:$B$103,A8) | C8: =COUNTIFS('테스트케이스'!$B$2:$B$103,$A8,'테스트케이스'!$H$2:$H$103,"P1") | D8: =COUNTIFS('테스트케이스'!$B$2:$B$103,$A8,'테스트케이스'!$H$2:$H$103,"P2") | E8: =COUNTIFS('테스트케이스'!$B$2:$B$103,$A8,'테스트케이스'!$H$2:$H$103,"P3") | F8: =COUNTIFS('테스트케이스'!$B$2:$B$103,$A8,'테스트케이스'!$N$2:$N$103,"Pass") | G8: =COUNTIFS('테스트케이스'!$B$2:$B$103,$A8,'테스트케이스'!$N$2:$N$103,"Fail") | H8: =COUNTIFS('테스트케이스'!$B$2:$B$103,$A8,'테스트케이스'!$N$2:$N$103,"Blocked") | I8: =B8-F8-G8-H8-COUNTIFS('테스트케이스'!$B$2:$B$103,$A8,'테스트케이스'!$N$2:$N$103,"N/A")
A9: 공통 계약 | B9: =COUNTIF('테스트케이스'!$B$2:$B$103,A9) | C9: =COUNTIFS('테스트케이스'!$B$2:$B$103,$A9,'테스트케이스'!$H$2:$H$103,"P1") | D9: =COUNTIFS('테스트케이스'!$B$2:$B$103,$A9,'테스트케이스'!$H$2:$H$103,"P2") | E9: =COUNTIFS('테스트케이스'!$B$2:$B$103,$A9,'테스트케이스'!$H$2:$H$103,"P3") | F9: =COUNTIFS('테스트케이스'!$B$2:$B$103,$A9,'테스트케이스'!$N$2:$N$103,"Pass") | G9: =COUNTIFS('테스트케이스'!$B$2:$B$103,$A9,'테스트케이스'!$N$2:$N$103,"Fail") | H9: =COUNTIFS('테스트케이스'!$B$2:$B$103,$A9,'테스트케이스'!$N$2:$N$103,"Blocked") | I9: =B9-F9-G9-H9-COUNTIFS('테스트케이스'!$B$2:$B$103,$A9,'테스트케이스'!$N$2:$N$103,"N/A")
A10: 응답 메시지 | B10: =COUNTIF('테스트케이스'!$B$2:$B$103,A10) | C10: =COUNTIFS('테스트케이스'!$B$2:$B$103,$A10,'테스트케이스'!$H$2:$H$103,"P1") | D10: =COUNTIFS('테스트케이스'!$B$2:$B$103,$A10,'테스트케이스'!$H$2:$H$103,"P2") | E10: =COUNTIFS('테스트케이스'!$B$2:$B$103,$A10,'테스트케이스'!$H$2:$H$103,"P3") | F10: =COUNTIFS('테스트케이스'!$B$2:$B$103,$A10,'테스트케이스'!$N$2:$N$103,"Pass") | G10: =COUNTIFS('테스트케이스'!$B$2:$B$103,$A10,'테스트케이스'!$N$2:$N$103,"Fail") | H10: =COUNTIFS('테스트케이스'!$B$2:$B$103,$A10,'테스트케이스'!$N$2:$N$103,"Blocked") | I10: =B10-F10-G10-H10-COUNTIFS('테스트케이스'!$B$2:$B$103,$A10,'테스트케이스'!$N$2:$N$103,"N/A")
A11: 푸시 메시지 | B11: =COUNTIF('테스트케이스'!$B$2:$B$103,A11) | C11: =COUNTIFS('테스트케이스'!$B$2:$B$103,$A11,'테스트케이스'!$H$2:$H$103,"P1") | D11: =COUNTIFS('테스트케이스'!$B$2:$B$103,$A11,'테스트케이스'!$H$2:$H$103,"P2") | E11: =COUNTIFS('테스트케이스'!$B$2:$B$103,$A11,'테스트케이스'!$H$2:$H$103,"P3") | F11: =COUNTIFS('테스트케이스'!$B$2:$B$103,$A11,'테스트케이스'!$N$2:$N$103,"Pass") | G11: =COUNTIFS('테스트케이스'!$B$2:$B$103,$A11,'테스트케이스'!$N$2:$N$103,"Fail") | H11: =COUNTIFS('테스트케이스'!$B$2:$B$103,$A11,'테스트케이스'!$N$2:$N$103,"Blocked") | I11: =B11-F11-G11-H11-COUNTIFS('테스트케이스'!$B$2:$B$103,$A11,'테스트케이스'!$N$2:$N$103,"N/A")
A12: 다중 발송 | B12: =COUNTIF('테스트케이스'!$B$2:$B$103,A12) | C12: =COUNTIFS('테스트케이스'!$B$2:$B$103,$A12,'테스트케이스'!$H$2:$H$103,"P1") | D12: =COUNTIFS('테스트케이스'!$B$2:$B$103,$A12,'테스트케이스'!$H$2:$H$103,"P2") | E12: =COUNTIFS('테스트케이스'!$B$2:$B$103,$A12,'테스트케이스'!$H$2:$H$103,"P3") | F12: =COUNTIFS('테스트케이스'!$B$2:$B$103,$A12,'테스트케이스'!$N$2:$N$103,"Pass") | G12: =COUNTIFS('테스트케이스'!$B$2:$B$103,$A12,'테스트케이스'!$N$2:$N$103,"Fail") | H12: =COUNTIFS('테스트케이스'!$B$2:$B$103,$A12,'테스트케이스'!$N$2:$N$103,"Blocked") | I12: =B12-F12-G12-H12-COUNTIFS('테스트케이스'!$B$2:$B$103,$A12,'테스트케이스'!$N$2:$N$103,"N/A")
A13: 멱등성·재시도 | B13: =COUNTIF('테스트케이스'!$B$2:$B$103,A13) | C13: =COUNTIFS('테스트케이스'!$B$2:$B$103,$A13,'테스트케이스'!$H$2:$H$103,"P1") | D13: =COUNTIFS('테스트케이스'!$B$2:$B$103,$A13,'테스트케이스'!$H$2:$H$103,"P2") | E13: =COUNTIFS('테스트케이스'!$B$2:$B$103,$A13,'테스트케이스'!$H$2:$H$103,"P3") | F13: =COUNTIFS('테스트케이스'!$B$2:$B$103,$A13,'테스트케이스'!$N$2:$N$103,"Pass") | G13: =COUNTIFS('테스트케이스'!$B$2:$B$103,$A13,'테스트케이스'!$N$2:$N$103,"Fail") | H13: =COUNTIFS('테스트케이스'!$B$2:$B$103,$A13,'테스트케이스'!$N$2:$N$103,"Blocked") | I13: =B13-F13-G13-H13-COUNTIFS('테스트케이스'!$B$2:$B$103,$A13,'테스트케이스'!$N$2:$N$103,"N/A")
A14: 메시지 객체 검증 | B14: =COUNTIF('테스트케이스'!$B$2:$B$103,A14) | C14: =COUNTIFS('테스트케이스'!$B$2:$B$103,$A14,'테스트케이스'!$H$2:$H$103,"P1") | D14: =COUNTIFS('테스트케이스'!$B$2:$B$103,$A14,'테스트케이스'!$H$2:$H$103,"P2") | E14: =COUNTIFS('테스트케이스'!$B$2:$B$103,$A14,'테스트케이스'!$H$2:$H$103,"P3") | F14: =COUNTIFS('테스트케이스'!$B$2:$B$103,$A14,'테스트케이스'!$N$2:$N$103,"Pass") | G14: =COUNTIFS('테스트케이스'!$B$2:$B$103,$A14,'테스트케이스'!$N$2:$N$103,"Fail") | H14: =COUNTIFS('테스트케이스'!$B$2:$B$103,$A14,'테스트케이스'!$N$2:$N$103,"Blocked") | I14: =B14-F14-G14-H14-COUNTIFS('테스트케이스'!$B$2:$B$103,$A14,'테스트케이스'!$N$2:$N$103,"N/A")
A15: 웹훅 수신·서명 | B15: =COUNTIF('테스트케이스'!$B$2:$B$103,A15) | C15: =COUNTIFS('테스트케이스'!$B$2:$B$103,$A15,'테스트케이스'!$H$2:$H$103,"P1") | D15: =COUNTIFS('테스트케이스'!$B$2:$B$103,$A15,'테스트케이스'!$H$2:$H$103,"P2") | E15: =COUNTIFS('테스트케이스'!$B$2:$B$103,$A15,'테스트케이스'!$H$2:$H$103,"P3") | F15: =COUNTIFS('테스트케이스'!$B$2:$B$103,$A15,'테스트케이스'!$N$2:$N$103,"Pass") | G15: =COUNTIFS('테스트케이스'!$B$2:$B$103,$A15,'테스트케이스'!$N$2:$N$103,"Fail") | H15: =COUNTIFS('테스트케이스'!$B$2:$B$103,$A15,'테스트케이스'!$N$2:$N$103,"Blocked") | I15: =B15-F15-G15-H15-COUNTIFS('테스트케이스'!$B$2:$B$103,$A15,'테스트케이스'!$N$2:$N$103,"N/A")
A16: 웹훅 설정·재전송 | B16: =COUNTIF('테스트케이스'!$B$2:$B$103,A16) | C16: =COUNTIFS('테스트케이스'!$B$2:$B$103,$A16,'테스트케이스'!$H$2:$H$103,"P1") | D16: =COUNTIFS('테스트케이스'!$B$2:$B$103,$A16,'테스트케이스'!$H$2:$H$103,"P2") | E16: =COUNTIFS('테스트케이스'!$B$2:$B$103,$A16,'테스트케이스'!$H$2:$H$103,"P3") | F16: =COUNTIFS('테스트케이스'!$B$2:$B$103,$A16,'테스트케이스'!$N$2:$N$103,"Pass") | G16: =COUNTIFS('테스트케이스'!$B$2:$B$103,$A16,'테스트케이스'!$N$2:$N$103,"Fail") | H16: =COUNTIFS('테스트케이스'!$B$2:$B$103,$A16,'테스트케이스'!$N$2:$N$103,"Blocked") | I16: =B16-F16-G16-H16-COUNTIFS('테스트케이스'!$B$2:$B$103,$A16,'테스트케이스'!$N$2:$N$103,"N/A")
A17: 레이트리밋·쿼터 | B17: =COUNTIF('테스트케이스'!$B$2:$B$103,A17) | C17: =COUNTIFS('테스트케이스'!$B$2:$B$103,$A17,'테스트케이스'!$H$2:$H$103,"P1") | D17: =COUNTIFS('테스트케이스'!$B$2:$B$103,$A17,'테스트케이스'!$H$2:$H$103,"P2") | E17: =COUNTIFS('테스트케이스'!$B$2:$B$103,$A17,'테스트케이스'!$H$2:$H$103,"P3") | F17: =COUNTIFS('테스트케이스'!$B$2:$B$103,$A17,'테스트케이스'!$N$2:$N$103,"Pass") | G17: =COUNTIFS('테스트케이스'!$B$2:$B$103,$A17,'테스트케이스'!$N$2:$N$103,"Fail") | H17: =COUNTIFS('테스트케이스'!$B$2:$B$103,$A17,'테스트케이스'!$N$2:$N$103,"Blocked") | I17: =B17-F17-G17-H17-COUNTIFS('테스트케이스'!$B$2:$B$103,$A17,'테스트케이스'!$N$2:$N$103,"N/A")
A18: 조회·페이지네이션 | B18: =COUNTIF('테스트케이스'!$B$2:$B$103,A18) | C18: =COUNTIFS('테스트케이스'!$B$2:$B$103,$A18,'테스트케이스'!$H$2:$H$103,"P1") | D18: =COUNTIFS('테스트케이스'!$B$2:$B$103,$A18,'테스트케이스'!$H$2:$H$103,"P2") | E18: =COUNTIFS('테스트케이스'!$B$2:$B$103,$A18,'테스트케이스'!$H$2:$H$103,"P3") | F18: =COUNTIFS('테스트케이스'!$B$2:$B$103,$A18,'테스트케이스'!$N$2:$N$103,"Pass") | G18: =COUNTIFS('테스트케이스'!$B$2:$B$103,$A18,'테스트케이스'!$N$2:$N$103,"Fail") | H18: =COUNTIFS('테스트케이스'!$B$2:$B$103,$A18,'테스트케이스'!$N$2:$N$103,"Blocked") | I18: =B18-F18-G18-H18-COUNTIFS('테스트케이스'!$B$2:$B$103,$A18,'테스트케이스'!$N$2:$N$103,"N/A")
A19: 보안·운영 | B19: =COUNTIF('테스트케이스'!$B$2:$B$103,A19) | C19: =COUNTIFS('테스트케이스'!$B$2:$B$103,$A19,'테스트케이스'!$H$2:$H$103,"P1") | D19: =COUNTIFS('테스트케이스'!$B$2:$B$103,$A19,'테스트케이스'!$H$2:$H$103,"P2") | E19: =COUNTIFS('테스트케이스'!$B$2:$B$103,$A19,'테스트케이스'!$H$2:$H$103,"P3") | F19: =COUNTIFS('테스트케이스'!$B$2:$B$103,$A19,'테스트케이스'!$N$2:$N$103,"Pass") | G19: =COUNTIFS('테스트케이스'!$B$2:$B$103,$A19,'테스트케이스'!$N$2:$N$103,"Fail") | H19: =COUNTIFS('테스트케이스'!$B$2:$B$103,$A19,'테스트케이스'!$N$2:$N$103,"Blocked") | I19: =B19-F19-G19-H19-COUNTIFS('테스트케이스'!$B$2:$B$103,$A19,'테스트케이스'!$N$2:$N$103,"N/A")
A20: 합계 | B20: =SUM(B8:B19) | C20: =SUM(C8:C19) | D20: =SUM(D8:D19) | E20: =SUM(E8:E19) | F20: =SUM(F8:F19) | G20: =SUM(G8:G19) | H20: =SUM(H8:H19) | I20: =SUM(I8:I19)
A21: 수행률 | B21: =IF(B20=0,0,(F20+G20+H20)/B20) | C21: Pass율 | D21: =IF((F20+G20)=0,0,F20/(F20+G20)) | E21: 수행률 = (Pass+Fail+Blocked)/TC 수, Pass율 = Pass/(Pass+Fail)
A23: 설계 근거별 분포
A24: 설계 근거 | B24: TC 수 | C24: P1 | D24: P2 | E24: P3 | F24: 비율
A25: 요구사항 | B25: =COUNTIF('테스트케이스'!$E$2:$E$103,A25) | C25: =COUNTIFS('테스트케이스'!$E$2:$E$103,$A25,'테스트케이스'!$H$2:$H$103,"P1") | D25: =COUNTIFS('테스트케이스'!$E$2:$E$103,$A25,'테스트케이스'!$H$2:$H$103,"P2") | E25: =COUNTIFS('테스트케이스'!$E$2:$E$103,$A25,'테스트케이스'!$H$2:$H$103,"P3") | F25: =IF($B$20=0,0,B25/$B$20)
A26: 리스크 기반 | B26: =COUNTIF('테스트케이스'!$E$2:$E$103,A26) | C26: =COUNTIFS('테스트케이스'!$E$2:$E$103,$A26,'테스트케이스'!$H$2:$H$103,"P1") | D26: =COUNTIFS('테스트케이스'!$E$2:$E$103,$A26,'테스트케이스'!$H$2:$H$103,"P2") | E26: =COUNTIFS('테스트케이스'!$E$2:$E$103,$A26,'테스트케이스'!$H$2:$H$103,"P3") | F26: =IF($B$20=0,0,B26/$B$20)
A27: 추가 검증 | B27: =COUNTIF('테스트케이스'!$E$2:$E$103,A27) | C27: =COUNTIFS('테스트케이스'!$E$2:$E$103,$A27,'테스트케이스'!$H$2:$H$103,"P1") | D27: =COUNTIFS('테스트케이스'!$E$2:$E$103,$A27,'테스트케이스'!$H$2:$H$103,"P2") | E27: =COUNTIFS('테스트케이스'!$E$2:$E$103,$A27,'테스트케이스'!$H$2:$H$103,"P3") | F27: =IF($B$20=0,0,B27/$B$20)
A29: 실행 구분별 결과
A30: 실행 구분 | B30: 대상 TC | C30: Pass | D30: Fail | E30: Blocked | F30: 미수행
A31: 무발송 | B31: =COUNTIF('테스트케이스'!$F$2:$F$103,A31) | C31: =COUNTIFS('테스트케이스'!$F$2:$F$103,$A31,'테스트케이스'!$N$2:$N$103,"Pass") | D31: =COUNTIFS('테스트케이스'!$F$2:$F$103,$A31,'테스트케이스'!$N$2:$N$103,"Fail") | E31: =COUNTIFS('테스트케이스'!$F$2:$F$103,$A31,'테스트케이스'!$N$2:$N$103,"Blocked") | F31: =B31-C31-D31-E31-COUNTIFS('테스트케이스'!$F$2:$F$103,$A31,'테스트케이스'!$N$2:$N$103,"N/A")
A32: 발송 | B32: =COUNTIF('테스트케이스'!$F$2:$F$103,A32) | C32: =COUNTIFS('테스트케이스'!$F$2:$F$103,$A32,'테스트케이스'!$N$2:$N$103,"Pass") | D32: =COUNTIFS('테스트케이스'!$F$2:$F$103,$A32,'테스트케이스'!$N$2:$N$103,"Fail") | E32: =COUNTIFS('테스트케이스'!$F$2:$F$103,$A32,'테스트케이스'!$N$2:$N$103,"Blocked") | F32: =B32-C32-D32-E32-COUNTIFS('테스트케이스'!$F$2:$F$103,$A32,'테스트케이스'!$N$2:$N$103,"N/A")
A33: 장기·한도 | B33: =COUNTIF('테스트케이스'!$F$2:$F$103,A33) | C33: =COUNTIFS('테스트케이스'!$F$2:$F$103,$A33,'테스트케이스'!$N$2:$N$103,"Pass") | D33: =COUNTIFS('테스트케이스'!$F$2:$F$103,$A33,'테스트케이스'!$N$2:$N$103,"Fail") | E33: =COUNTIFS('테스트케이스'!$F$2:$F$103,$A33,'테스트케이스'!$N$2:$N$103,"Blocked") | F33: =B33-C33-D33-E33-COUNTIFS('테스트케이스'!$F$2:$F$103,$A33,'테스트케이스'!$N$2:$N$103,"N/A")
A35: 자동화 구분별 분포(테스트 피라미드)
A36: 자동화 구분 | B36: TC 수 | C36: P1 | D36: P2 | E36: P3 | F36: 비율
A37: API | B37: =COUNTIF('테스트케이스'!$G$2:$G$103,A37) | C37: =COUNTIFS('테스트케이스'!$G$2:$G$103,$A37,'테스트케이스'!$H$2:$H$103,"P1") | D37: =COUNTIFS('테스트케이스'!$G$2:$G$103,$A37,'테스트케이스'!$H$2:$H$103,"P2") | E37: =COUNTIFS('테스트케이스'!$G$2:$G$103,$A37,'테스트케이스'!$H$2:$H$103,"P3") | F37: =IF($B$20=0,0,B37/$B$20)
A38: UI | B38: =COUNTIF('테스트케이스'!$G$2:$G$103,A38) | C38: =COUNTIFS('테스트케이스'!$G$2:$G$103,$A38,'테스트케이스'!$H$2:$H$103,"P1") | D38: =COUNTIFS('테스트케이스'!$G$2:$G$103,$A38,'테스트케이스'!$H$2:$H$103,"P2") | E38: =COUNTIFS('테스트케이스'!$G$2:$G$103,$A38,'테스트케이스'!$H$2:$H$103,"P3") | F38: =IF($B$20=0,0,B38/$B$20)
A39: 수동 | B39: =COUNTIF('테스트케이스'!$G$2:$G$103,A39) | C39: =COUNTIFS('테스트케이스'!$G$2:$G$103,$A39,'테스트케이스'!$H$2:$H$103,"P1") | D39: =COUNTIFS('테스트케이스'!$G$2:$G$103,$A39,'테스트케이스'!$H$2:$H$103,"P2") | E39: =COUNTIFS('테스트케이스'!$G$2:$G$103,$A39,'테스트케이스'!$H$2:$H$103,"P3") | F39: =IF($B$20=0,0,B39/$B$20)
A40: ※ API: pytest+httpx로 플랫폼·모의 서버 응답을 코드로 검증 / UI: LINE 앱 도달·표시, Developers Console 확인 필요 / 수동: 시간 경과·운영 통제·코드 리뷰. 상세는 계획서 8장
A42: 요구사항 커버리지
A43: 요구사항 ID | B43: 연결 TC 수 | C43: 요구사항 기반 | D43: Pass | E43: Fail | J43: 요구사항
A44: REQ-01 | B44: =COUNTIF('테스트케이스'!$D$2:$D$103,"*"&A44&"*") | C44: =COUNTIFS('테스트케이스'!$D$2:$D$103,"*"&A44&"*",'테스트케이스'!$E$2:$E$103,"요구사항") | D44: =COUNTIFS('테스트케이스'!$D$2:$D$103,"*"&A44&"*",'테스트케이스'!$N$2:$N$103,"Pass") | E44: =COUNTIFS('테스트케이스'!$D$2:$D$103,"*"&A44&"*",'테스트케이스'!$N$2:$N$103,"Fail") | J44: 모든 Messaging API 엔드포인트는 Authorization: Bearer {channel access token} 헤더가 필수이며, 유효한 토큰이 없으면 401 Unauthorized를 반환한다. 권한이 없는 리소스는 403 Forbidden이다.
A45: REQ-02 | B45: =COUNTIF('테스트케이스'!$D$2:$D$103,"*"&A45&"*") | C45: =COUNTIFS('테스트케이스'!$D$2:$D$103,"*"&A45&"*",'테스트케이스'!$E$2:$E$103,"요구사항") | D45: =COUNTIFS('테스트케이스'!$D$2:$D$103,"*"&A45&"*",'테스트케이스'!$N$2:$N$103,"Pass") | E45: =COUNTIFS('테스트케이스'!$D$2:$D$103,"*"&A45&"*",'테스트케이스'!$N$2:$N$103,"Fail") | J45: 채널 액세스 토큰은 4종이다. v2.1(사용자 지정 만료, 최대 30일, 채널당 30개, 초과 발급 요청은 거부), stateless(15분, 발급 수 무제한, 폐기 불가), short-lived(30일, 30개, 초과 시 가장 오래된 토큰 폐기), long-lived(무기한, 1개, 재발급 시 기존 토큰 무효). 만료된 토큰은 발급 수에 포함되지 않는다.
...

Sheet 테스트케이스
A1: TC ID | B1: 대분류 | C1: 중분류 | D1: 요구사항 ID | E1: 설계 근거 | F1: 실행 구분 | G1: 자동화 구분 | H1: 우선순위 | I1: 사전 조건 | J1: 테스트 절차 | K1: 테스트 데이터 | L1: 기대 결과 | M1: 관련 질의 | N1: 결과 | O1: 실측·메모 | P1: 결함 ID | Q1: 수행일 | R1: 수행자 | S1: 증적(요청·응답 로그) | T1: 비고
A2: TC-AUTH-001 | B2: 인증·토큰 | C2: stateless 발급 | D2: REQ-02, REQ-03 | E2: 요구사항 | F2: 무발송 | G2: API | H2: P1 | I2: 테스트 채널 CH1의 채널 ID·채널 secret 확보 | J2: 1. POST https://api.line.me/oauth2/v3/token, Content-Type: application/x-www-form-urlencoded 2. grant_type=client_credentials, client_id={채널 ID}, client_secret={secret} 전송 3. 응답 본문·헤더 확인 4. 발급된 토큰으로 GET /v2/bot/info 호출 | K2: CH1 자격 증명 | L2: 1. 200, 본문에 token_type='Bearer', access_token(문자열), expires_in=900(15분)이 있다 2. X-Line-Request-Id 헤더가 있다 3. 발급 토큰으로 GET /v2/bot/info가 200을 반환한다
A3: TC-AUTH-002 | B3: 인증·토큰 | C3: stateless 발급 실패 | D3: REQ-03, REQ-05 | E3: 요구사항 | F3: 무발송 | G3: API | H3: P1 | I3: CH1 채널 ID 확보 | J3: 1. client_secret을 마지막 1자만 바꾼 값으로 POST /oauth2/v3/token 2. client_id를 존재하지 않는 숫자로 바꿔 재요청 3. grant_type을 'password'로 바꿔 재요청 4. 각 응답의 상태 코드·본문 기록 | K3: 잘못된 secret / 무효 채널 ID / 미지원 grant_type | L3: 1~3. 모두 400이며 본문에 오류를 설명하는 message가 있다(access_token 미포함) 4. 오류 본문에 채널 secret 값이 그대로 노출되지 않는다
A4: TC-AUTH-003 | B4: 인증·토큰 | C4: v2.1 발급(JWT) | D4: REQ-02, REQ-03 | E4: 요구사항 | F4: 무발송 | G4: API | H4: P2 | I4: CH1에 assertion 서명 키(JWK) 등록, 개인 키 보관 | J4: 1. 만료 30분 이내의 JWT assertion 생성(token_exp=3600 지정) 2. POST /oauth2/v2.1/token, grant_type=client_credentials, client_assertion_type=urn:ietf:params:oauth:client-assertion-type:jwt-bearer, client_assertion={JWT} 3. 응답 확인 4. GET /oauth2/v2.1/verify?access_token={발급 토큰} 호출 | K4: JWT(만료 30분 내), token_exp 3600 | L4: 1. 200, access_token·expires_in(≈3600)·token_type='Bearer'·key_id 반환 2. verify가 200으로 client_id(=채널 ID), expires_in(≤3600)을 반환한다
A5: TC-AUTH-004 | B5: 인증·토큰 | C5: v2.1 발급 실패 | D5: REQ-03 | E5: 요구사항 | F5: 무발송 | G5: API | H5: P2 | I5: TC-AUTH-003과 동일 | J5: 1. exp가 생성 시각 + 31분인 JWT로 발급 요청 2. 등록되지 않은 키로 서명한 JWT로 발급 요청 3. 서명 부분을 1바이트 바꾼 JWT로 발급 요청 | K5: 만료 초과 JWT / 미등록 키 JWT / 서명 변조 JWT | L5: 1. 400(JWT assertion 만료) 2. 404(채널에 미등록 서명 키) 3. 400(JWT 검증 실패) 각 본문에 message가 있다
A6: TC-AUTH-005 | B6: 인증·토큰 | C6: v2.1 발급 한도 | D6: REQ-02, REQ-03 | E6: 요구사항 | F6: 장기·한도 | G6: 수동 | H6: P2 | I6: CH1에 유효한 v2.1 토큰이 0개(기존 토큰은 revoke) | J6: 1. token_exp=86400(1일)으로 v2.1 토큰을 30개 발급 2. 31번째 발급 요청 3. GET /oauth2/v2.1/tokens/kid로 유효 key_id 목록 조회 4. 1개를 revoke 후 다시 발급 요청 | K6: JWT 31개(각각 새 jti) | L6: 1. 30개 모두 200 2. 31번째는 400(발급 가능 수 초과 message) 3. key_id 30개가 조회된다 4. revoke 후 발급은 200(만료·폐기 토큰은 집계 제외)
A7: TC-AUTH-006 | B7: 인증·토큰 | C7: 토큰 폐기 | D7: REQ-02, REQ-03, REQ-01 | E7: 요구사항 | F7: 무발송 | G7: API | H7: P1 | I7: v2.1 토큰 T3 발급 완료 | J7: 1. T3로 GET /v2/bot/info → 200 확인 2. POST /oauth2/v2.1/revoke (client_id, client_secret, access_token=T3) 3. 즉시 T3로 GET /v2/bot/info 재호출 4. GET /oauth2/v2.1/verify?access_token=T3 | K7: T3 | L7: 2. 200 3. 401(폐기 직후부터 사용 불가) 4. 400(미존재·폐기 토큰)
A8: TC-AUTH-007 | B8: 인증·토큰 | C8: stateless 폐기 불가 | D8: REQ-02 | E8: 요구사항 | F8: 무발송 | G8: API | H8: P3 | I8: stateless 토큰 T2 발급 | J8: 1. POST /oauth2/v2.1/revoke에 access_token=T2로 요청 2. POST /v2/oauth/revoke(short/long-lived용)에 T2로 요청 3. 각 응답 후 T2로 GET /v2/bot/info | K8: T2 | L8: 1~2. 폐기가 거부되거나(4xx) 무시된다 — 상태 코드·message 기록 3. T2는 15분 만료 전까지 계속 200(문서: stateless 토큰은 폐기 불가)
A9: TC-AUTH-008 | B9: 인증·토큰 | C9: 만료 토큰 | D9: REQ-01, REQ-02, REQ-03 | E9: 요구사항 | F9: 장기·한도 | G9: 수동 | H9: P1 | I9: stateless 토큰 T2를 발급하고 발급 시각 기록 | J9: 1. 발급 14분 50초 시점에 GET /v2/bot/info 2. 발급 15분 10초 시점에 같은 호출 3. 응답 상태·message 기록 | K9: T2, 타이머 | L9: 1. 200 2. 401, message에 인증 실패 사유('Authentication failed due to the following reason: …')가 있다 3. 만료 전후 경계(±10초)에서 동작이 전환된다
A10: TC-AUTH-009 | B10: 인증·토큰 | C10: Authorization 헤더 변형 | D10: REQ-01, REQ-05 | E10: 리스크 기반 | F10: 무발송 | G10: API | H10: P1 | I10: 유효 long-lived 토큰 T1 | J10: 1. Authorization 헤더 없이 GET /v2/bot/info 2. 'Bearer ' 뒤 빈 문자열 3. 'bearer {T1}'(소문자 스킴) 4. 'Bearer {T1}'(공백 2개) 5. '{T1}'(스킴 없음) 6. 'Bearer {T1 마지막 1자 변경}' 7. 'Basic {base64}' | K10: T1 변형 7종 | L10: 1~2, 5~7. 401이며 본문 message가 있고 토큰 값이 에코되지 않는다 3~4. 현재 동작 기록(Q05 회신 후 확정). 모든 401 응답에 X-Line-Request-Id가 있다 | M10: Q05
A11: TC-CMN-001 | B11: 공통 계약 | C11: 성공 응답 스키마 | D11: REQ-04, REQ-05 | E11: 요구사항 | F11: 무발송 | G11: API | H11: P1 | I11: T1 유효 | J11: 1. GET /v2/bot/info 호출 2. 응답 헤더·본문을 JSON 스키마(userId, basicId, displayName, chatMode, markAsReadMode; premiumId·pictureUrl 선택)로 검증 3. 같은 호출 3회 반복해 X-Line-Request-Id 비교 | K11: T1 | L11: 1. 200, Content-Type이 application/json 2. 필수 필드 존재·타입 일치, 선택 필드는 없어도 통과(비파괴 추가 허용) 3. 요청마다 다른 X-Line-Request-Id(UUID 형식)가 발급된다
A12: TC-CMN-002 | B12: 공통 계약 | C12: 오류 응답 스키마 | D12: REQ-05, REQ-12 | E12: 요구사항 | F12: 무발송 | G12: API | H12: P1 | I12: T1 유효 | J12: 1. POST /v2/bot/message/validate/push에 messages=[{type:'text', text:''}, {type:'unknown'}] 전송 2. 본문을 오류 스키마(message: string 필수, details: [{message, property}] 조건부)로 검증 3. details 각 항목의 property가 요청 JSON 경로(messages[0].text, messages[1].type)를 가리키는지 확인 | K12: 무효 메시지 2건 | L12: 1. 400 2. message='The request body has 2 error(s)' 형식, details 2개 3. details[0].property='messages[0].text', message='May not be empty'; details[1].property='messages[1].type', message에 허용 type 목록이 있다
A13: TC-CMN-003 | B13: 공통 계약 | C13: JSON 파싱 오류 | D13: REQ-04, REQ-05 | E13: 요구사항 | F13: 무발송 | G13: API | H13: P2 | I13: T1 유효 | J13: 1. POST /v2/bot/message/validate/push에 본문 '{"messages": [' (닫히지 않은 JSON) 2. 본문 '' (빈 문자열) 3. 본문 'messages=text' (폼 형식) | K13: 깨진 JSON 3종 | L13: 1. 400, message가 'The request body could not be parsed as JSON (line: X, column: Y)' 형식 2~3. 400이며 message가 있다. 500이 나오면 결함
A14: TC-CMN-004 | B14: 공통 계약 | C14: Content-Type 변형 | D14: REQ-04, REQ-05 | E14: 요구사항 | F14: 무발송 | G14: API | H14: P2 | I14: T1 유효, 유효 텍스트 메시지 본문 | J14: 1. Content-Type 헤더 없이 validate/push 전송 2. Content-Type: text/plain 3. Content-Type: application/json; charset=utf-8 4. Content-Type: multipart/form-data | K14: 유효 본문 + Content-Type 4종 | L14: 3. 200(charset 파라미터 허용 기대) 1, 2, 4. 400 또는 415이며 message가 'The content type, XXX, is not supported' 형식인지 기록(Q06 회신 후 확정) | M14: Q06
A15: TC-CMN-005 | B15: 공통 계약 | C15: 요청 크기 상한 | D15: REQ-04 | E15: 리스크 기반 | F15: 무발송 | G15: API | H15: P2 | I15: T1 유효 | J15: 1. 약 1.9MB의 Flex 메시지 본문(긴 텍스트 컴포넌트 반복)으로 validate/push 2. 약 2.1MB 본문으로 validate/push 3. 응답 시간·상태 기록 | K15: 본문 1.9MB / 2.1MB | L15: 1. 400 또는 200(메시지 객체 자체 제한에 따름) — 413이 아니어야 한다 2. 413 Payload Too Large 두 경우 모두 연결이 끊기지 않고 JSON 오류 본문이 온다
A16: TC-CMN-006 | B16: 공통 계약 | C16: 경로·메서드 정확성 | D16: REQ-21, REQ-04 | E16: 추가 검증 | F16: 무발송 | G16: API | H16: P3 | I16: T1 유효 | J16: 1. GET /v2/bot/info/ (끝 슬래시) 2. GET /v2/bot/Info (대문자) 3. POST /v2/bot/info (메서드 불일치) 4. GET /v2/bot/message/push (메서드 불일치) | K16: 경로·메서드 변형 | L16: 1. 문서상 동작 보장 안 됨 — 결과 기록(404 예상) 2. 404 3~4. 404 또는 405이며 500이 아니다
A17: TC-CMN-007 | B17: 공통 계약 | C17: 미지 필드 무시 | D17: REQ-22 | E17: 요구사항 | F17: 무발송 | G17: API | H17: P2 | I17: T1 유효 | J17: 1. validate/push 본문에 정의되지 않은 최상위 필드 'extra': 1 추가 2. 메시지 객체에 정의되지 않은 필드 'foo': 'bar' 추가 3. 각각 응답 확인 | K17: 유효 텍스트 메시지 + 미지 필드 | L17: 1~2. 현재 동작 기록: 200(무시) 또는 400(엄격 검증). 어느 쪽이든 클라이언트 SDK가 미지 응답 필드를 무시하도록 설계(비파괴 변경 대비)되어야 하며, 결과는 자동화 assertion 기준으로 채택
A18: TC-CMN-008 | B18: 공통 계약 | C18: 응답 필드 추가 내성 | D18: REQ-22 | E18: 리스크 기반 | F18: 무발송 | G18: API | H18: P2 | I18: 모의 서버 MK1 구동, 클라이언트(SDK 래퍼) 준비 | J18: 1. MK1이 GET /v2/bot/info 응답에 미지 필드 'newField'를 추가하고 필드 순서를 바꿔 반환하도록 설정 2. 웹훅 수신 본문에 미지 이벤트 type 'futureEvent'와 미지 속성이 포함된 요청을 봇서버 B1에 전송 3. 클라이언트·봇서버 동작 확인 | K18: MK1 응답 변형, 미지 이벤트 웹훅 | L18: 1. 클라이언트가 예외 없이 기존 필드를 파싱한다 2. 봇서버가 미지 이벤트를 무시(로그만)하고 200을 반환하며 같은 배열의 다른 이벤트는 정상 처리한다
A19: TC-CMN-009 | B19: 공통 계약 | C19: 도메인 분리 | D19: REQ-20 | E19: 요구사항 | F19: 무발송 | G19: API | H19: P3 | I19: T1 유효, 웹훅으로 받은 이미지 messageId | J19: 1. GET https://api.line.me/v2/bot/message/{messageId}/content (잘못된 도메인) 2. GET https://api-data.line.me/v2/bot/message/{messageId}/content (정상 도메인) | K19: 이미지 messageId | L19: 1. 404 또는 오류(문서: 콘텐츠는 api-data 도메인) 2. 200, Content-Type이 image/*이고 바이너리가 수신된다
A20: TC-RPL-001 | B20: 응답 메시지 | C20: 정상 응답 | D20: REQ-06, REQ-15 | E20: 요구사항 | F20: 발송 | G20: UI | H20: P1 | I20: 봇서버 B1 웹훅 수신 중, 테스트 사용자 U1이 CH1 친구 | J20: 1. U1이 LINE 앱에서 봇에 텍스트 전송 2. B1이 수신한 message 이벤트의 replyToken·webhookEventId 기록 3. 10초 내 POST /v2/bot/message/reply(replyToken, messages=[text 1건]) 4. 응답 본문 확인, U1 앱에서 도달 확인 | K20: U1, 텍스트 1건 | L20: 3. 200, sentMessages[0].id(숫자 문자열)와 quoteToken이 있다 4. U1 채팅방에 메시지가 표시된다
A21: TC-RPL-002 | B21: 응답 메시지 | C21: 토큰 재사용 | D21: REQ-06, REQ-05 | E21: 요구사항 | F21: 발송 | G21: API | H21: P1 | I21: TC-RPL-001 직후, 같은 replyToken 보유 | J21: 1. 같은 replyToken으로 reply 재요청 2. 응답 상태·본문 기록 | K21: 사용된 replyToken | L21: 1. 400, message='Invalid reply token' 2. U1에게 두 번째 메시지가 도달하지 않는다
A22: TC-RPL-003 | B22: 응답 메시지 | C22: 토큰 만료 경계 | D22: REQ-06 | E22: 요구사항 | F22: 발송 | G22: 수동 | H22: P2 | I22: B1 수신 중, U1 메시지 3건을 시차를 두고 전송해 replyToken 3개 확보 | J22: 1. 토큰 A는 수신 55초 후 reply 2. 토큰 B는 수신 65초 후 reply 3. 토큰 C는 수신 20분 30초 후 reply 4. 각 결과를 3회(별도 토큰) 반복 측정 | K22: replyToken 3개 × 3회 | L22: 1. 200(1분 이내 보장) 2~3. 400 'Invalid reply token' 예상이나 문서상 비보장 영역 — 분포를 기록하고 '관찰'로 판정(Q07). 설계 결론: 토큰은 수신 즉시 사용 | M22: Q07
A23: TC-RPL-004 | B23: 응답 메시지 | C23: 메시지 수 경계 | D23: REQ-06, REQ-12 | E23: 요구사항 | F23: 발송 | G23: UI | H23: P1 | I23: replyToken 2개 확보(각각 1분 내 사용) | J23: 1. messages 5개(text 5건)로 reply 2. 새 토큰으로 messages 6개로 reply 3. 새 토큰으로 messages 0개([])로 reply | K23: 텍스트 5건 / 6건 / 0건 | L23: 1. 200, sentMessages 5개, U1에 5건 도달 2. 400, details.property가 messages를 가리킨다(Q04) 3. 400 — 발송 없음 | M23: Q04
A24: TC-RPL-005 | B24: 응답 메시지 | C24: 재전송 웹훅 토큰 | D24: REQ-06, REQ-16 | E24: 요구사항 | F24: 발송 | G24: 수동 | H24: P2 | I24: CH1 웹훅 재전송 ON, B1을 500 응답 모드로 설정 | J24: 1. U1이 봇에 메시지 전송 → B1이 500 반환(토큰 미사용, 기록만) 2. B1을 200 모드로 복구하고 재전송 웹훅(isRedelivery=true) 수신 대기 3. 재전송 수신 1분 내 그 replyToken으로 reply 4. 별도 건: 원본에서 토큰을 사용한 뒤 재전송 토큰으로 reply | K24: U1, B1 응답 모드 전환 | L24: 2. 재전송 이벤트의 replyToken·webhookEventId가 원본과 동일하다 3. 200(원본 미사용 + 발생 20분 이내) 4. 400 'Invalid reply token'
A25: TC-RPL-006 | B25: 응답 메시지 | C25: standby 모드 | D25: REQ-15 | E25: 요구사항 | F25: 무발송 | G25: API | H25: P3 | I25: B1 수신 중(모듈 채널 연동 환경은 없음) | J25: 1. B1에 mode='standby'이고 replyToken이 없는 message 이벤트를 서명 포함해 로컬 주입 2. 봇서버 처리 로직 확인 | K25: standby 이벤트 샘플 | L25: 1. 봇서버가 reply/push를 시도하지 않고 200만 반환한다(문서: standby 중 발송 금지) 2. 로그에 standby 사유가 남는다
A26: TC-RPL-007 | B26: 응답 메시지 | C26: 리트라이 키 미지원 | D26: REQ-11 | E26: 요구사항 | F26: 발송 | G26: API | H26: P2 | I26: replyToken 1개 확보 | J26: 1. reply 요청에 X-Line-Retry-Key: {UUID} 헤더 추가 2. 응답 기록 | K26: 유효 replyToken, UUID | L26: 1. 400(미지원 엔드포인트에 리트라이 키 지정) 2. 메시지 미발송, 토큰은 소모되지 않아 키 없이 재요청하면 200(확인용)
A27: TC-PSH-001 | B27: 푸시 메시지 | C27: 정상 발송(user) | D27: REQ-07 | E27: 요구사항 | F27: 발송 | G27: UI | H27: P1 | I27: U1이 CH1 친구, U1 userId 확보(웹훅 source.userId) | J27: 1. POST /v2/bot/message/push {to: U1, messages: [text]} + X-Line-Retry-Key 2. 응답 본문·헤더 확인 3. U1 앱에서 도달·알림 확인 | K27: U1, 텍스트 1건, RK1 | L27: 1. 200, sentMessages[0].id·quoteToken 2. X-Line-Request-Id 존재 3. 메시지 도달, 푸시 알림 수신
A28: TC-PSH-002 | B28: 푸시 메시지 | C28: 정상 발송(group) | D28: REQ-07, REQ-15 | E28: 요구사항 | F28: 발송 | G28: UI | H28: P2 | I28: 봇이 그룹 G1에 참여, G1 groupId 확보 | J28: 1. to=G1 groupId로 push 2. 그룹 채팅에서 도달 확인 | K28: G1 | L28: 1. 200 2. 그룹의 모든 구성원에게 메시지가 표시된다
A29: TC-PSH-003 | B29: 푸시 메시지 | C29: 차단 사용자 | D29: REQ-07 | E29: 요구사항 | F29: 발송 | G29: UI | H29: P1 | I29: U2가 CH1을 친구 추가 후 차단 | J29: 1. to=U2로 push 2. 응답 기록 3. U2 앱에서 차단 해제 후 채팅방 확인 | K29: U2(차단) | L29: 1. 200(문서: 차단 사용자도 200) 2. sentMessages가 반환된다 3. 차단 중 보낸 메시지는 표시되지 않는다(미도달) — 발송 성공 ≠ 도달을 설계 노트에 반영
A30: TC-PSH-004 | B30: 푸시 메시지 | C30: 타 채널 userId | D30: REQ-07, REQ-05 | E30: 요구사항 | F30: 발송 | G30: API | H30: P1 | I30: 다른 프로바이더 채널 CH2에서 얻은 U1의 userId(값이 다름) 확보 | J30: 1. CH1 토큰으로 to={CH2 기준 userId}로 push 1회 2. 응답 기록(가이드라인상 무효 ID 반복 요청 금지 — 1회만) | K30: CH2 userId | L30: 1. 400, message='Failed to send messages' 계열 2. 미도달
A31: TC-PSH-005 | B31: 푸시 메시지 | C31: 미참여 그룹 | D31: REQ-07 | E31: 요구사항 | F31: 발송 | G31: API | H31: P2 | I31: 봇이 탈퇴한 그룹 G2의 groupId 확보 | J31: 1. to=G2로 push 1회 | K31: G2 | L31: 1. 400, 발송 없음
A32: TC-PSH-006 | B32: 푸시 메시지 | C32: 7일 창(미친구) | D32: REQ-07 | E32: 요구사항 | F32: 발송 | G32: 수동 | H32: P2 | I32: U3가 친구 추가 없이 봇에 1:1 메시지를 보낸 지 1일 이내 | J32: 1. to=U3로 push 2. U3 앱 확인 3. (장기) 8일 후 같은 요청 | K32: U3 | L32: 1. 200 2. 도달한다(7일 창) 3. 200이지만 미도달 — 결과 기록
A33: TC-PSH-007 | B33: 푸시 메시지 | C33: notificationDisabled | D33: REQ-07 | E33: 요구사항 | F33: 발송 | G33: UI | H33: P3 | I33: U1 알림 허용 상태 | J33: 1. notificationDisabled=true로 push 2. notificationDisabled=false로 push 3. notificationDisabled='true'(문자열)로 push | K33: U1 | L33: 1. 200, 메시지는 도달하지만 알림 배너·소리 없음 2. 200, 알림 수신 3. 현재 동작 기록(Q12) | M33: Q12
A34: TC-PSH-008 | B34: 푸시 메시지 | C34: customAggregationUnits 검증 | D34: REQ-07, REQ-05 | E34: 요구사항 | F34: 발송 | G34: API | H34: P2 | I34: U1 | J34: 1. customAggregationUnits=['promo_A'] (유효) 2. ['promo-A'] (하이픈) 3. ['a'*30] / ['a'*31] 4. ['u1','u2'] (2개) 5. [] (빈 배열) | K34: 유닛명 변형 | L34: 1. 200; 3의 30자는 200 2, 3의 31자. 400 'The request body has 1 error(s)', details.property가 customAggregationUnits를 가리킨다 4~5. 현재 동작 기록(Q12) | M34: Q12
A35: TC-PSH-009 | B35: 푸시 메시지 | C35: to 필드 검증 | D35: REQ-07, REQ-05 | E35: 요구사항 | F35: 무발송 | G35: API | H35: P2 | I35: T1 | J35: 1. to 누락 2. to='' 3. to='user123'(형식 불일치) 4. to=['U…'] (배열) | K35: to 변형 4종 | L35: 1~4. 400이며 details[].property='to'. 미도달. 500이 나오면 결함
A36: TC-MLT-001 | B36: 다중 발송 | C36: multicast 정상 | D36: REQ-08 | E36: 요구사항 | F36: 발송 | G36: UI | H36: P1 | I36: U1·U2(차단 해제 상태) 모두 친구 | J36: 1. POST /v2/bot/message/multicast {to:[U1,U2], messages:[text]} + 리트라이 키 2. 두 사용자 앱 확인 | K36: U1, U2 | L36: 1. 200, 본문 '{}' 2. 두 명 모두 도달
A37: TC-MLT-002 | B37: 다중 발송 | C37: multicast 수신자 수 경계 | D37: REQ-08 | E37: 요구사항 | F37: 무발송 | G37: API | H37: P1 | I37: validate/multicast는 messages만 검증하므로 to 경계는 실제 엔드포인트로 검증. 유효 userId 1개(U1) | J37: 1. to에 U1 1개 + 형식은 유효하나 존재하지 않는 ID 499개(총 500)로 multicast — 가이드라인상 무효 ID 요청 금지이므로 **사내 테스트 환경·모의 서버 MK1 전제** 2. 501개로 요청 3. 0개([])로 요청 | K37: to 500 / 501 / 0 (MK1) | L37: 1. 200 2. 400, details.property='to' 3. 400 또는 현재 동작 기록(Q03) ※ 실플랫폼에서는 500개 실사용자 확보 불가 → 모의 서버에서 계약 검증, 실플랫폼은 2명으로 스모크만 | M37: Q03
A38: TC-MLT-003 | B38: 다중 발송 | C38: multicast 중복·그룹 ID | D38: REQ-08 | E38: 요구사항 | F38: 발송 | G38: UI | H38: P2 | I38: U1, G1 groupId | J38: 1. to=[U1, U1] (중복) 2. to=[G1 groupId] 3. to=[U1, {CH2 userId}] (혼합) — 1회만 | K38: 중복 / 그룹 / 혼합 | L38: 2. 400(그룹·룸 불가) 1, 3. 현재 동작 기록(Q03): 중복 시 도달 건수(1건인지 2건인지), 혼합 시 400인지 U1만 도달인지 | M38: Q03
A39: TC-MLT-004 | B39: 다중 발송 | C39: multicast 전체 실패 원자성 | D39: REQ-08 | E39: 요구사항 | F39: 발송 | G39: UI | H39: P1 | I39: U1, U2 친구 | J39: 1. to=[U1,U2], messages=[유효 text, {type:'text', text:''}]로 multicast 2. 두 사용자 앱 확인 | K39: 유효+무효 메시지 혼합 | L39: 1. 400 2. 누구에게도 어떤 메시지도 도달하지 않는다(문서: 오류 시 아무에게도 발송 안 됨)
A40: TC-MLT-005 | B40: 다중 발송 | C40: broadcast 정상 | D40: REQ-09 | E40: 요구사항 | F40: 발송 | G40: UI | H40: P2 | I40: CH1 친구가 테스트 계정(U1·U2·U3)뿐임을 확인 | J40: 1. POST /v2/bot/message/broadcast {messages:[text]} + 리트라이 키 2. 친구 전원 앱 확인 3. GET /v2/bot/message/quota/consumption 전후 비교 | K40: 텍스트 1건 | L40: 1. 200, '{}' 2. 친구 전원 도달(차단 중인 사용자는 미도달) 3. totalUsage가 도달 대상 수만큼 증가(근사치)
...

Sheet 테스트 데이터
A1: 구분 | B1: ID | C1: 이름 | D1: 조건 | E1: 사용 TC | F1: 준비 완료 | G1: 실제 값(ID·URL·버전 등, 비밀값 제외)
A2: 채널 | B2: CH1 | C2: 메인 테스트 채널 | D2: 개인 프로바이더의 Messaging API 채널. Webhook 사용 ON·재전송 ON, 채널 ID·secret·long-lived 토큰 확보, assertion 서명 키 등록. 월 무료 메시지 한도 내 운영 | E2: 대부분의 TC
A3: 채널 | B3: CH2 | C3: 타 프로바이더 채널 | D3: 다른 프로바이더 아래 두 번째 채널(userId가 CH1과 다름). verified 아님 | E3: TC-PSH-004, TC-MLT-003, TC-RLM-003, TC-PGN-005
A4: 계정 | B4: U1 | C4: 메인 테스트 사용자 | D4: 본인 LINE 계정. CH1 친구, 프로필 동의, 알림 허용. userId는 웹훅 source.userId에서 확보 | E4: 발송·웹훅 TC 전반
A5: 계정 | B5: U2 | C5: 차단 상태 사용자 | D5: 보조 계정. CH1 친구 추가 후 차단(필요 시 해제). 그룹 G1 구성원 | E5: TC-PSH-003, TC-MLT-001/004, TC-WHK-009, TC-PGN-006
A6: 계정 | B6: U3 | C6: 미친구 발신 사용자 | D6: 보조 계정. CH1을 친구 추가하지 않고 1:1 메시지를 보낸 지 7일 이내 | E6: TC-PSH-006, TC-PGN-006
A7: 그룹 | B7: G1 | C7: 봇 참여 그룹 | D7: U1·U2·봇이 구성원. groupId는 join 이벤트에서 확보 | E7: TC-PSH-002, TC-MLT-003, TC-WHK-012, TC-PGN-008
A8: 그룹 | B8: G2 | C8: 봇 탈퇴 그룹 | D8: 봇이 참여했다가 탈퇴한 그룹의 groupId | E8: TC-PSH-005
A9: 서버 | B9: B1 | C9: 봇서버 | D9: 로컬 FastAPI + ngrok HTTPS. 서명 검증, 원문 body·헤더·IP 로그, webhookEventId 중복 제거, 응답 모드(200/500/지연 5·15·30초/종료)를 설정으로 전환 | E9: 웹훅 TC 전반
A10: 서버 | B10: MK1 | C10: LINE API 모의 서버 | D10: LINE API 응답을 흉내 내는 로컬 서버. 429·500·타임아웃·409·월 한도 429·필드 추가·to 500건 시나리오를 재현. 가이드라인상 실플랫폼 부하·무효 ID 요청 금지를 대체 | E10: TC-CMN-008, TC-MLT-002/006/010, TC-IDM-007/008, TC-RLM-001/003/005/006
A11: 토큰 | B11: T1 | C11: long-lived 토큰 | D11: 콘솔에서 발급. 기본 인증용 | E11: 기본
A12: 토큰 | B12: T2 | C12: stateless 토큰 | D12: POST /oauth2/v3/token으로 발급(15분) | E12: TC-AUTH-001, 007, 008
A13: 토큰 | B13: T3 | C13: v2.1 토큰 | D13: JWT assertion으로 발급(token_exp 3600) | E13: TC-AUTH-003~006
... A18: 키 | B18: RK1~RK7 | C18: 리트라이 키 | D18: uuid4()로 생성한 소문자 하이픈 UUID. 케이스마다 새 값 | E18: TC-IDM 그룹, 발송 TC
A20: ※ 채널 secret·토큰·개인 키는 이 파일에 기록하지 않는다(환경 변수·비밀 저장소). 실제 값 열에는 식별자·URL·버전만 적는다

Sheet 질의사항
A1: ID | B1: 질의 | C1: 영향 | D1: 회신 전 처리 | E1: 영향 TC 수 | F1: 영향 TC | G1: 확인 결과(실제 응답) | H1: 확인일
A2: Q01 | B2: 리트라이 키 형식 검증 범위: UUID 형식이 아닌 문자열('abc'), 대문자 UUID, 중괄호 포함 UUID, 빈 문자열을 X-Line-Retry-Key에 넣었을 때 400인지 그대로 수락되는지, 수락되면 멱등 키로 동작하는지 | C2: 멱등성·재시도 TC | D2: 모의 서버가 아닌 테스트 채널에 1회씩 보내 상태 코드·message 기록 후 판정 | E2: =COUNTIF('테스트케이스'!$M$2:$M$103,"*"&A2&"*") | F2: IDM-006
A3: Q02 | B3: 같은 리트라이 키로 본문(수신자·메시지 내용)을 바꿔 재요청하면 409(키 기준 차단)인지 신규 처리인지. 문서는 '예상대로 동작하지 않을 수 있음'만 명시 | C3: 멱등성 TC, 운영 리스크 | D3: 현재 동작(상태 코드, accepted-request-id, 실제 도달 메시지) 기록 후 판정 | E3: =COUNTIF('테스트케이스'!$M$2:$M$103,"*"&A3&"*") | F3: IDM-004
A4: Q03 | B4: multicast to 배열 경계: 빈 배열, 같은 userId 중복, 유효 ID와 타채널 ID 혼합일 때 400인지 부분 발송인지, 중복이 500 한도 계산에 포함되는지 | C4: 다중 발송 TC | D4: 현재 동작(상태 코드, details[].property, 도달 건수) 기록 후 판정 | E4: =COUNTIF('테스트케이스'!$M$2:$M$103,"*"&A4&"*") | F4: MLT-002, MLT-003
A5: Q04 | B5: messages 배열 경계의 오류 표기: 빈 배열([])과 6개 초과 시 message·details[].property 값(messages 인지 messages[5] 인지), 5개 중 1개만 무효일 때 property 인덱스 표기 | C5: 메시지 객체 검증 TC, 자동화 assertion | D5: validate 엔드포인트로 현재 응답 본문을 기록해 assertion 기준으로 채택 | E5: =COUNTIF('테스트케이스'!$M$2:$M$103,"*"&A5&"*") | F5: RPL-004, MSG-004
A6: Q05 | B6: Authorization 헤더 변형 처리: 스킴 소문자('bearer'), 공백 2개, 스킴 없이 토큰만, 빈 토큰, 헤더 자체 누락일 때 모두 401인지, message가 'Authentication failed due to the following reason: XXX' 형식인지 | C6: 인증 TC | D6: 조회성 엔드포인트(GET /v2/bot/info)로 현재 동작 기록 후 판정 | E6: =COUNTIF('테스트케이스'!$M$2:$M$103,"*"&A6&"*") | F6: AUTH-009
A7: Q06 | B7: Content-Type 처리: 헤더 누락, text/plain으로 JSON 전송, application/json; charset=utf-8, multipart일 때 400/415 중 무엇이고 'The content type, XXX, is not supported' 메시지가 나오는지 | C7: 공통 계약 TC | D7: validate 엔드포인트로 현재 동작 기록 후 판정 | E7: =COUNTIF('테스트케이스'!$M$2:$M$103,"*"&A7&"*") | F7: CMN-004
A8: Q07 | B8: reply token 만료 경계: 수신 후 59초/60초/61초/20분 시점의 실제 거부 여부와 오류 message. 문서는 '1분 이후 동작 보장 안 됨'으로 비결정을 명시하고 '시간 제한에 의존하지 말 것'을 권고 | C8: 응답 메시지 TC(비결정 영역) | D8: 각 시점 3회 측정해 결과 분포를 기록하고 Pass/Fail 대신 '관찰'로 판정, 설계 권고(즉시 사용)로 처리 | E8: =COUNTIF('테스트케이스'!$M$2:$M$103,"*"&A8&"*") | F8: RPL-003
A9: Q08 | B9: 429 응답의 세부: Retry-After 헤더 포함 여부, 본문 details 유무, 토큰 버킷 보충 속도(초당 몇 건 회복), 월 한도 429와 레이트리밋 429의 message 외 구분자 | C9: 레이트리밋 TC, 클라이언트 백오프 설계 | D9: 가이드라인상 실플랫폼에 한도 초과 요청 금지. 한도가 낮은 webhook test(60/h)에서 1회 초과만 관찰해 헤더·본문 기록 | E9: =COUNTIF('테스트케이스'!$M$2:$M$103,"*"&A9&"*") | F9: RLM-001, RLM-002, RLM-005
A10: Q09 | B10: 웹훅 재전송의 횟수·간격(비공개)과 봇서버 응답 타임아웃 기준 초. 타임아웃으로 간주되는 지연 시간과 재전송 종료 후 콘솔 통계 반영 시점 | C10: 웹훅 재전송 TC | D10: 봇서버 지연을 5/15/30초로 바꿔 콘솔 통계(reason)와 재전송 도착 시각을 기록해 역도출 | E10: =COUNTIF('테스트케이스'!$M$2:$M$103,"*"&A10&"*") | F10: WHS-003, WHS-005
A11: Q10 | B11: followers/ids의 limit 범위 외 값(0, 음수, 1001, 문자열)과 start에 임의 문자열 지정 시 400인지 기본값·최대값으로 보정되는지, 오류 property 값 | C11: 페이지네이션 TC | D11: 현재 동작 기록 후 판정. verified 계정이 아니면 403으로 Blocked 처리 | E11: =COUNTIF('테스트케이스'!$M$2:$M$103,"*"&A11&"*") | F11: PGN-002, PGN-004
A12: Q11 | B12: text 길이 경계의 오류 표기: 5001자(UTF-16 유닛) 초과 시 details[].property·message, LINE 이모지 대체 텍스트 치환 후 길이가 5000을 넘는 경우의 처리, 4999자 + 서로게이트 이모지 1개(=5001유닛)의 판정 | C12: 메시지 객체 검증 TC | D12: validate 엔드포인트로 현재 응답 기록 후 판정 | E12: =COUNTIF('테스트케이스'!$M$2:$M$103,"*"&A12&"*") | F12: MSG-001, MSG-002, MSG-003
A13: Q12 | B13: 선택 파라미터 타입·조합 검증: notificationDisabled에 문자열 'true'/숫자 1, customAggregationUnits에 빈 배열·2개, to에 groupId + customAggregationUnits 조합일 때 400인지 무시되는지 | C13: 푸시 메시지 TC | D13: validate가 아닌 push 본문 검증이므로 테스트 사용자(U1)에게 1회씩 보내 현재 동작 기록 | E13: =COUNTIF('테스트케이스'!$M$2:$M$103,"*"&A13&"*") | F13: PSH-007, PSH-008
A14: Q13 | B14: webhook test 엔드포인트의 endpoint 파라미터에 http://(비HTTPS), 501자 URL, 해석 불가 도메인, 포트 포함 URL을 지정했을 때의 상태 코드(400 vs 200+success=false)와 reason 값 | C14: 웹훅 설정 TC | D14: 현재 동작 기록 후 판정. 60 req/h 한도 내에서 수행 | E14: =COUNTIF('테스트케이스'!$M$2:$M$103,"*"&A14&"*") | F14: WHS-004
A16: ※ 영향 TC 목록은 2026-10-25 설계 시점 기준. TC의 '관련 질의' 열을 바꾸면 '영향 TC 수'만 자동 갱신됨

Sheet API 체크리스트
A1: 관점 | B1: 확인 항목 | C1: 연결 TC | D1: 비고
A2: 계약·스키마 | B2: 성공·오류 응답 필드·타입, Content-Type, 미지 필드 내성 | C2: TC-CMN-001, TC-CMN-002, TC-CMN-007, TC-CMN-008
A3: 인증·권한 | B3: 토큰 종류·만료·폐기, 401/403, 헤더 변형 | C3: TC-AUTH-001 ~ TC-AUTH-009, TC-PGN-005
A4: 상태 코드·오류 포맷 | B4: 400/404/409/410/413/429의 message·details·property | C4: TC-CMN-002 ~ TC-CMN-006, TC-RPL-002, TC-PGN-006/007
A5: 입력 검증·경계 | B5: 길이(UTF-16)·개수·열거값·형식·URL 인코딩 | C5: TC-MSG-001 ~ TC-MSG-007, TC-MSG-011, TC-PSH-008/009, TC-WHS-002
A6: 멱등성·재시도 | B6: 리트라이 키 409·24h·본문 불일치, 상태 코드별 재시도 정책 | C6: TC-IDM-001 ~ TC-IDM-008, TC-RPL-007
A7: 비동기·상태 조회 | B7: 202 수락 후 phase 전이, 상태 창 만료, 콘텐츠 준비 202 | C7: TC-MLT-007 ~ TC-MLT-010, TC-PGN-007
A8: 페이지네이션 | B8: limit 경계, next 순회 완전성, continuation token 만료 | C8: TC-PGN-001 ~ TC-PGN-004
A9: 레이트리밋·쿼터 | B9: 429 두 종류 구분, 토큰 버킷 회복, 채널·메서드 단위, 월 한도 조회 | C9: TC-RLM-001 ~ TC-RLM-006, TC-MLT-006
A10: 웹훅 보안(서명) | B10: HMAC-SHA256 원문 검증, 불일치·누락 거부, secret 교체, IP 제한 금지 | C10: TC-WHK-002 ~ TC-WHK-005, TC-WHK-007, TC-SEC-002/005/006
A11: 웹훅 신뢰성 | B11: 200 즉시 응답, 재전송 동일성, webhookEventId 중복 제거, timestamp 순서 | C11: TC-WHK-006, TC-WHK-010, TC-WHS-005 ~ TC-WHS-007, TC-RPL-005
A12: 발송 성공 ≠ 도달 | B12: 차단·탈퇴·미친구 200 미도달, multicast 원자성, 7일 창 | C12: TC-PSH-003 ~ TC-PSH-006, TC-MLT-004
A13: 호환성·관측성 | B13: 비파괴 변경 내성, request id·로그 보관·마스킹 | C13: TC-CMN-007, TC-CMN-008, TC-WHK-011, TC-SEC-003, TC-SEC-004
A15: ※ 플랫폼 API 테스트 관점 목록. 각 관점이 최소 1개 TC로 연결되도록 설계. 다른 공개 API 설계에 재사용 가능

Sheet 결함 리포트
A1: 결함 ID | B1: TC ID | C1: 제목 | D1: 심각도 | E1: 우선순위 | F1: 환경(채널/엔드포인트/SDK 버전) | G1: 재현 절차 | H1: 기대 결과 | I1: 실제 결과 | J1: 재현율 | K1: 첨부(X-Line-Request-Id·로그) | L1: 상태 | M1: 등록일 | N1: 비고
A2: DEF-000 | B2: TC-IDM-001 | C2: (예시) 같은 리트라이 키 재요청이 409가 아닌 200으로 처리되어 메시지가 2건 도달 | D2: S1 | E2: P1 | F2: CH1 / POST /v2/bot/message/push / httpx 0.27 | G2: 1. push + X-Line-Retry-Key(UUID) → 200 2. 같은 본문·키로 10초 후 재요청 3. U1 앱에서 도달 건수 확인 | H2: 409 + X-Line-Accepted-Request-Id, 도달 1건 | I2: 200, sentMessages.id가 다른 값, 도달 2건 | J2: 3/3 | K2: req-id a1b2…, b3c4… / push.log | L2: 신규 | M2: 2026-10-26 | N2: 예시 행 — 실제 결함 등록 시 삭제
A25: 심각도 기준
A26: S1 | B26: 중복 발송, 메시지 유실, 서명 미검증으로 위조 웹훅 처리, 토큰·secret 노출
A27: S2 | B27: 계약 위반(상태 코드·오류 포맷 불일치), 경계값 오판정, 재시도 정책 오동작
A28: S3 | B28: 오류 메시지 문구·필드명 불일치, 우회 가능한 클라이언트 이상
A29: S4 | B29: 개선 제안, 로그 형식 등 사소한 사항
