Workbook

Sheet 요약
A1: 무신사 iOS 앱 주문 플로우 테스트 케이스
A2: - 요구사항 15건(REQ-01~15)은 무신사 공개 정책(고객센터 FAQ·이용 안내, 2026-10-25 조회)에서 역도출. 질의사항 12건(Q01~Q12)은 앱 동작으로 확정하며 기대결과에 'Qn 회신 후 확정' 표기
A3: - 설계 근거: 요구사항(공개 정책에서 직접 도출) / 리스크 기반(정책 외, 금액·주문 상태 영향 큼) / 추가 검증(범위 외 품질 확인)
A4: - 입력: '테스트케이스' 시트 노란 칸. 결과는 Pass/Fail/Blocked/N/A 선택. 집계는 자동 계산
A5: - 실행 구분: 비결제(결제 승인 전까지) / 실결제(소액 1건, 완료 후 즉시 취소) / 장기(48시간 대기 등). 자동화 구분: API / UI / 수동 — 계획서 8장 자동화 전략의 계층 배치
A7: 대분류 | B7: TC 수 | C7: P1 | D7: P2 | E7: P3 | F7: Pass | G7: Fail | H7: Blocked | I7: 미완료
A8: 장바구니 | B8: =COUNTIF('테스트케이스'!$B$2:$B$91,A8) | C8: =COUNTIFS('테스트케이스'!$B$2:$B$91,$A8,'테스트케이스'!$H$2:$H$91,"P1") | D8: =COUNTIFS('테스트케이스'!$B$2:$B$91,$A8,'테스트케이스'!$H$2:$H$91,"P2") | E8: =COUNTIFS('테스트케이스'!$B$2:$B$91,$A8,'테스트케이스'!$H$2:$H$91,"P3") | F8: =COUNTIFS('테스트케이스'!$B$2:$B$91,$A8,'테스트케이스'!$N$2:$N$91,"Pass") | G8: =COUNTIFS('테스트케이스'!$B$2:$B$91,$A8,'테스트케이스'!$N$2:$N$91,"Fail") | H8: =COUNTIFS('테스트케이스'!$B$2:$B$91,$A8,'테스트케이스'!$N$2:$N$91,"Blocked") | I8: =B8-F8-G8-H8-COUNTIFS('테스트케이스'!$B$2:$B$91,$A8,'테스트케이스'!$N$2:$N$91,"N/A")
A9: 주문서·금액 | B9: =COUNTIF('테스트케이스'!$B$2:$B$91,A9) | C9: =COUNTIFS('테스트케이스'!$B$2:$B$91,$A9,'테스트케이스'!$H$2:$H$91,"P1") | D9: =COUNTIFS('테스트케이스'!$B$2:$B$91,$A9,'테스트케이스'!$H$2:$H$91,"P2") | E9: =COUNTIFS('테스트케이스'!$B$2:$B$91,$A9,'테스트케이스'!$H$2:$H$91,"P3") | F9: =COUNTIFS('테스트케이스'!$B$2:$B$91,$A9,'테스트케이스'!$N$2:$N$91,"Pass") | G9: =COUNTIFS('테스트케이스'!$B$2:$B$91,$A9,'테스트케이스'!$N$2:$N$91,"Fail") | H9: =COUNTIFS('테스트케이스'!$B$2:$B$91,$A9,'테스트케이스'!$N$2:$N$91,"Blocked") | I9: =B9-F9-G9-H9-COUNTIFS('테스트케이스'!$B$2:$B$91,$A9,'테스트케이스'!$N$2:$N$91,"N/A")
A10: 쿠폰 | B10: =COUNTIF('테스트케이스'!$B$2:$B$91,A10) | C10: =COUNTIFS('테스트케이스'!$B$2:$B$91,$A10,'테스트케이스'!$H$2:$H$91,"P1") | D10: =COUNTIFS('테스트케이스'!$B$2:$B$91,$A10,'테스트케이스'!$H$2:$H$91,"P2") | E10: =COUNTIFS('테스트케이스'!$B$2:$B$91,$A10,'테스트케이스'!$H$2:$H$91,"P3") | F10: =COUNTIFS('테스트케이스'!$B$2:$B$91,$A10,'테스트케이스'!$N$2:$N$91,"Pass") | G10: =COUNTIFS('테스트케이스'!$B$2:$B$91,$A10,'테스트케이스'!$N$2:$N$91,"Fail") | H10: =COUNTIFS('테스트케이스'!$B$2:$B$91,$A10,'테스트케이스'!$N$2:$N$91,"Blocked") | I10: =B10-F10-G10-H10-COUNTIFS('테스트케이스'!$B$2:$B$91,$A10,'테스트케이스'!$N$2:$N$91,"N/A")
A11: 적립금 | B11: =COUNTIF('테스트케이스'!$B$2:$B$91,A11) | C11: =COUNTIFS('테스트케이스'!$B$2:$B$91,$A11,'테스트케이스'!$H$2:$H$91,"P1") | D11: =COUNTIFS('테스트케이스'!$B$2:$B$91,$A11,'테스트케이스'!$H$2:$H$91,"P2") | E11: =COUNTIFS('테스트케이스'!$B$2:$B$91,$A11,'테스트케이스'!$H$2:$H$91,"P3") | F11: =COUNTIFS('테스트케이스'!$B$2:$B$91,$A11,'테스트케이스'!$N$2:$N$91,"Pass") | G11: =COUNTIFS('테스트케이스'!$B$2:$B$91,$A11,'테스트케이스'!$N$2:$N$91,"Fail") | H11: =COUNTIFS('테스트케이스'!$B$2:$B$91,$A11,'테스트케이스'!$N$2:$N$91,"Blocked") | I11: =B11-F11-G11-H11-COUNTIFS('테스트케이스'!$B$2:$B$91,$A11,'테스트케이스'!$N$2:$N$91,"N/A")
A12: 배송지·배송비 | B12: =COUNTIF('테스트케이스'!$B$2:$B$91,A12) | C12: =COUNTIFS('테스트케이스'!$B$2:$B$91,$A12,'테스트케이스'!$H$2:$H$91,"P1") | D12: =COUNTIFS('테스트케이스'!$B$2:$B$91,$A12,'테스트케이스'!$H$2:$H$91,"P2") | E12: =COUNTIFS('테스트케이스'!$B$2:$B$91,$A12,'테스트케이스'!$H$2:$H$91,"P3") | F12: =COUNTIFS('테스트케이스'!$B$2:$B$91,$A12,'테스트케이스'!$N$2:$N$91,"Pass") | G12: =COUNTIFS('테스트케이스'!$B$2:$B$91,$A12,'테스트케이스'!$N$2:$N$91,"Fail") | H12: =COUNTIFS('테스트케이스'!$B$2:$B$91,$A12,'테스트케이스'!$N$2:$N$91,"Blocked") | I12: =B12-F12-G12-H12-COUNTIFS('테스트케이스'!$B$2:$B$91,$A12,'테스트케이스'!$N$2:$N$91,"N/A")
A13: 결제수단 | B13: =COUNTIF('테스트케이스'!$B$2:$B$91,A13) | C13: =COUNTIFS('테스트케이스'!$B$2:$B$91,$A13,'테스트케이스'!$H$2:$H$91,"P1") | D13: =COUNTIFS('테스트케이스'!$B$2:$B$91,$A13,'테스트케이스'!$H$2:$H$91,"P2") | E13: =COUNTIFS('테스트케이스'!$B$2:$B$91,$A13,'테스트케이스'!$H$2:$H$91,"P3") | F13: =COUNTIFS('테스트케이스'!$B$2:$B$91,$A13,'테스트케이스'!$N$2:$N$91,"Pass") | G13: =COUNTIFS('테스트케이스'!$B$2:$B$91,$A13,'테스트케이스'!$N$2:$N$91,"Fail") | H13: =COUNTIFS('테스트케이스'!$B$2:$B$91,$A13,'테스트케이스'!$N$2:$N$91,"Blocked") | I13: =B13-F13-G13-H13-COUNTIFS('테스트케이스'!$B$2:$B$91,$A13,'테스트케이스'!$N$2:$N$91,"N/A")
A14: 주문 취소·상태 | B14: =COUNTIF('테스트케이스'!$B$2:$B$91,A14) | C14: =COUNTIFS('테스트케이스'!$B$2:$B$91,$A14,'테스트케이스'!$H$2:$H$91,"P1") | D14: =COUNTIFS('테스트케이스'!$B$2:$B$91,$A14,'테스트케이스'!$H$2:$H$91,"P2") | E14: =COUNTIFS('테스트케이스'!$B$2:$B$91,$A14,'테스트케이스'!$H$2:$H$91,"P3") | F14: =COUNTIFS('테스트케이스'!$B$2:$B$91,$A14,'테스트케이스'!$N$2:$N$91,"Pass") | G14: =COUNTIFS('테스트케이스'!$B$2:$B$91,$A14,'테스트케이스'!$N$2:$N$91,"Fail") | H14: =COUNTIFS('테스트케이스'!$B$2:$B$91,$A14,'테스트케이스'!$N$2:$N$91,"Blocked") | I14: =B14-F14-G14-H14-COUNTIFS('테스트케이스'!$B$2:$B$91,$A14,'테스트케이스'!$N$2:$N$91,"N/A")
A15: 모바일 특화 | B15: =COUNTIF('테스트케이스'!$B$2:$B$91,A15) | C15: =COUNTIFS('테스트케이스'!$B$2:$B$91,$A15,'테스트케이스'!$H$2:$H$91,"P1") | D15: =COUNTIFS('테스트케이스'!$B$2:$B$91,$A15,'테스트케이스'!$H$2:$H$91,"P2") | E15: =COUNTIFS('테스트케이스'!$B$2:$B$91,$A15,'테스트케이스'!$H$2:$H$91,"P3") | F15: =COUNTIFS('테스트케이스'!$B$2:$B$91,$A15,'테스트케이스'!$N$2:$N$91,"Pass") | G15: =COUNTIFS('테스트케이스'!$B$2:$B$91,$A15,'테스트케이스'!$N$2:$N$91,"Fail") | H15: =COUNTIFS('테스트케이스'!$B$2:$B$91,$A15,'테스트케이스'!$N$2:$N$91,"Blocked") | I15: =B15-F15-G15-H15-COUNTIFS('테스트케이스'!$B$2:$B$91,$A15,'테스트케이스'!$N$2:$N$91,"N/A")
A16: 보안·입력 검증 | B16: =COUNTIF('테스트케이스'!$B$2:$B$91,A16) | C16: =COUNTIFS('테스트케이스'!$B$2:$B$91,$A16,'테스트케이스'!$H$2:$H$91,"P1") | D16: =COUNTIFS('테스트케이스'!$B$2:$B$91,$A16,'테스트케이스'!$H$2:$H$91,"P2") | E16: =COUNTIFS('테스트케이스'!$B$2:$B$91,$A16,'테스트케이스'!$H$2:$H$91,"P3") | F16: =COUNTIFS('테스트케이스'!$B$2:$B$91,$A16,'테스트케이스'!$N$2:$N$91,"Pass") | G16: =COUNTIFS('테스트케이스'!$B$2:$B$91,$A16,'테스트케이스'!$N$2:$N$91,"Fail") | H16: =COUNTIFS('테스트케이스'!$B$2:$B$91,$A16,'테스트케이스'!$N$2:$N$91,"Blocked") | I16: =B16-F16-G16-H16-COUNTIFS('테스트케이스'!$B$2:$B$91,$A16,'테스트케이스'!$N$2:$N$91,"N/A")
A17: 호환성·접근성 | B17: =COUNTIF('테스트케이스'!$B$2:$B$91,A17) | C17: =COUNTIFS('테스트케이스'!$B$2:$B$91,$A17,'테스트케이스'!$H$2:$H$91,"P1") | D17: =COUNTIFS('테스트케이스'!$B$2:$B$91,$A17,'테스트케이스'!$H$2:$H$91,"P2") | E17: =COUNTIFS('테스트케이스'!$B$2:$B$91,$A17,'테스트케이스'!$H$2:$H$91,"P3") | F17: =COUNTIFS('테스트케이스'!$B$2:$B$91,$A17,'테스트케이스'!$N$2:$N$91,"Pass") | G17: =COUNTIFS('테스트케이스'!$B$2:$B$91,$A17,'테스트케이스'!$N$2:$N$91,"Fail") | H17: =COUNTIFS('테스트케이스'!$B$2:$B$91,$A17,'테스트케이스'!$N$2:$N$91,"Blocked") | I17: =B17-F17-G17-H17-COUNTIFS('테스트케이스'!$B$2:$B$91,$A17,'테스트케이스'!$N$2:$N$91,"N/A")
A18: 합계 | B18: =SUM(B8:B17) | C18: =SUM(C8:C17) | D18: =SUM(D8:D17) | E18: =SUM(E8:E17) | F18: =SUM(F8:F17) | G18: =SUM(G8:G17) | H18: =SUM(H8:H17) | I18: =SUM(I8:I17)
A19: 수행률 | B19: =IF(B18=0,0,(F18+G18+H18)/B18) | C19: Pass율 | D19: =IF((F18+G18)=0,0,F18/(F18+G18)) | E19: 수행률 = (Pass+Fail+Blocked)/TC 수, Pass율 = Pass/(Pass+Fail)
A21: 설계 근거별 분포
A22: 설계 근거 | B22: TC 수 | C22: P1 | D22: P2 | E22: P3 | F22: 비율
A23: 요구사항 | B23: =COUNTIF('테스트케이스'!$E$2:$E$91,A23) | C23: =COUNTIFS('테스트케이스'!$E$2:$E$91,$A23,'테스트케이스'!$H$2:$H$91,"P1") | D23: =COUNTIFS('테스트케이스'!$E$2:$E$91,$A23,'테스트케이스'!$H$2:$H$91,"P2") | E23: =COUNTIFS('테스트케이스'!$E$2:$E$91,$A23,'테스트케이스'!$H$2:$H$91,"P3") | F23: =IF($B$18=0,0,B23/$B$18)
A24: 리스크 기반 | B24: =COUNTIF('테스트케이스'!$E$2:$E$91,A24) | C24: =COUNTIFS('테스트케이스'!$E$2:$E$91,$A24,'테스트케이스'!$H$2:$H$91,"P1") | D24: =COUNTIFS('테스트케이스'!$E$2:$E$91,$A24,'테스트케이스'!$H$2:$H$91,"P2") | E24: =COUNTIFS('테스트케이스'!$E$2:$E$91,$A24,'테스트케이스'!$H$2:$H$91,"P3") | F24: =IF($B$18=0,0,B24/$B$18)
A25: 추가 검증 | B25: =COUNTIF('테스트케이스'!$E$2:$E$91,A25) | C25: =COUNTIFS('테스트케이스'!$E$2:$E$91,$A25,'테스트케이스'!$H$2:$H$91,"P1") | D25: =COUNTIFS('테스트케이스'!$E$2:$E$91,$A25,'테스트케이스'!$H$2:$H$91,"P2") | E25: =COUNTIFS('테스트케이스'!$E$2:$E$91,$A25,'테스트케이스'!$H$2:$H$91,"P3") | F25: =IF($B$18=0,0,B25/$B$18)
A27: 실행 구분별 결과
A28: 실행 구분 | B28: 대상 TC | C28: Pass | D28: Fail | E28: Blocked | F28: 미수행
A29: 비결제 | B29: =COUNTIF('테스트케이스'!$F$2:$F$91,A29) | C29: =COUNTIFS('테스트케이스'!$F$2:$F$91,$A29,'테스트케이스'!$N$2:$N$91,"Pass") | D29: =COUNTIFS('테스트케이스'!$F$2:$F$91,$A29,'테스트케이스'!$N$2:$N$91,"Fail") | E29: =COUNTIFS('테스트케이스'!$F$2:$F$91,$A29,'테스트케이스'!$N$2:$N$91,"Blocked") | F29: =B29-C29-D29-E29-COUNTIFS('테스트케이스'!$F$2:$F$91,$A29,'테스트케이스'!$N$2:$N$91,"N/A")
A30: 실결제 | B30: =COUNTIF('테스트케이스'!$F$2:$F$91,A30) | C30: =COUNTIFS('테스트케이스'!$F$2:$F$91,$A30,'테스트케이스'!$N$2:$N$91,"Pass") | D30: =COUNTIFS('테스트케이스'!$F$2:$F$91,$A30,'테스트케이스'!$N$2:$N$91,"Fail") | E30: =COUNTIFS('테스트케이스'!$F$2:$F$91,$A30,'테스트케이스'!$N$2:$N$91,"Blocked") | F30: =B30-C30-D30-E30-COUNTIFS('테스트케이스'!$F$2:$F$91,$A30,'테스트케이스'!$N$2:$N$91,"N/A")
A31: 장기 | B31: =COUNTIF('테스트케이스'!$F$2:$F$91,A31) | C31: =COUNTIFS('테스트케이스'!$F$2:$F$91,$A31,'테스트케이스'!$N$2:$N$91,"Pass") | D31: =COUNTIFS('테스트케이스'!$F$2:$F$91,$A31,'테스트케이스'!$N$2:$N$91,"Fail") | E31: =COUNTIFS('테스트케이스'!$F$2:$F$91,$A31,'테스트케이스'!$N$2:$N$91,"Blocked") | F31: =B31-C31-D31-E31-COUNTIFS('테스트케이스'!$F$2:$F$91,$A31,'테스트케이스'!$N$2:$N$91,"N/A")
A33: 자동화 구분별 분포(테스트 피라미드)
A34: 자동화 구분 | B34: TC 수 | C34: P1 | D34: P2 | E34: P3 | F34: 비율
A35: API | B35: =COUNTIF('테스트케이스'!$G$2:$G$91,A35) | C35: =COUNTIFS('테스트케이스'!$G$2:$G$91,$A35,'테스트케이스'!$H$2:$H$91,"P1") | D35: =COUNTIFS('테스트케이스'!$G$2:$G$91,$A35,'테스트케이스'!$H$2:$H$91,"P2") | E35: =COUNTIFS('테스트케이스'!$G$2:$G$91,$A35,'테스트케이스'!$H$2:$H$91,"P3") | F35: =IF($B$18=0,0,B35/$B$18)
A36: UI | B36: =COUNTIF('테스트케이스'!$G$2:$G$91,A36) | C36: =COUNTIFS('테스트케이스'!$G$2:$G$91,$A36,'테스트케이스'!$H$2:$H$91,"P1") | D36: =COUNTIFS('테스트케이스'!$G$2:$G$91,$A36,'테스트케이스'!$H$2:$H$91,"P2") | E36: =COUNTIFS('테스트케이스'!$G$2:$G$91,$A36,'테스트케이스'!$H$2:$H$91,"P3") | F36: =IF($B$18=0,0,B36/$B$18)
A37: 수동 | B37: =COUNTIF('테스트케이스'!$G$2:$G$91,A37) | C37: =COUNTIFS('테스트케이스'!$G$2:$G$91,$A37,'테스트케이스'!$H$2:$H$91,"P1") | D37: =COUNTIFS('테스트케이스'!$G$2:$G$91,$A37,'테스트케이스'!$H$2:$H$91,"P2") | E37: =COUNTIFS('테스트케이스'!$G$2:$G$91,$A37,'테스트케이스'!$H$2:$H$91,"P3") | F37: =IF($B$18=0,0,B37/$B$18)
A38: ※ API: 주문서 계산·주문·취소 API 레벨(사내 테스트 환경 전제) / UI: Appium(XCUITest) E2E / 수동: 환경·OS 통합·육안 판단. 상세는 계획서 8장
A40: 요구사항 커버리지
A41: 요구사항 ID | B41: 연결 TC 수 | C41: 요구사항 기반 | D41: Pass | E41: Fail | J41: 요구사항
A42: REQ-01 | B42: =COUNTIF('테스트케이스'!$D$2:$D$91,"*"&A42&"*") | C42: =COUNTIFS('테스트케이스'!$D$2:$D$91,"*"&A42&"*",'테스트케이스'!$E$2:$E$91,"요구사항") | D42: =COUNTIFS('테스트케이스'!$D$2:$D$91,"*"&A42&"*",'테스트케이스'!$N$2:$N$91,"Pass") | E42: =COUNTIFS('테스트케이스'!$D$2:$D$91,"*"&A42&"*",'테스트케이스'!$N$2:$N$91,"Fail") | J42: 결제 수단은 무신사머니 / 무신사페이 / 일반 결제(신용카드, 가상계좌, Apple Pay, 휴대폰, 토스페이, 카카오페이, 삼성페이, KBPay, 페이코) 중 하나만 선택할 수 있으며 복합 결제는 불가하다.
A43: REQ-02 | B43: =COUNTIF('테스트케이스'!$D$2:$D$91,"*"&A43&"*") | C43: =COUNTIFS('테스트케이스'!$D$2:$D$91,"*"&A43&"*",'테스트케이스'!$E$2:$E$91,"요구사항") | D43: =COUNTIFS('테스트케이스'!$D$2:$D$91,"*"&A43&"*",'테스트케이스'!$N$2:$N$91,"Pass") | E43: =COUNTIFS('테스트케이스'!$D$2:$D$91,"*"&A43&"*",'테스트케이스'!$N$2:$N$91,"Fail") | J43: 주문 시점에 진행 중인 결제수단 즉시 할인 혜택이 있으면 해당 결제수단이 자동 선택되어 노출되고, 다른 결제수단으로 바꾸려면 즉시 할인을 먼저 해제해야 한다.
A44: REQ-03 | B44: =COUNTIF('테스트케이스'!$D$2:$D$91,"*"&A44&"*") | C44: =COUNTIFS('테스트케이스'!$D$2:$D$91,"*"&A44&"*",'테스트케이스'!$E$2:$E$91,"요구사항") | D44: =COUNTIFS('테스트케이스'!$D$2:$D$91,"*"&A44&"*",'테스트케이스'!$N$2:$N$91,"Pass") | E44: =COUNTIFS('테스트케이스'!$D$2:$D$91,"*"&A44&"*",'테스트케이스'!$N$2:$N$91,"Fail") | J44: 적립금은 5,000원 이상 보유한 경우에만 사용할 수 있다.
A45: REQ-04 | B45: =COUNTIF('테스트케이스'!$D$2:$D$91,"*"&A45&"*") | C45: =COUNTIFS('테스트케이스'!$D$2:$D$91,"*"&A45&"*",'테스트케이스'!$E$2:$E$91,"요구사항") | D45: =COUNTIFS('테스트케이스'!$D$2:$D$91,"*"&A45&"*",'테스트케이스'!$N$2:$N$91,"Pass") | E45: =COUNTIFS('테스트케이스'!$D$2:$D$91,"*"&A45&"*",'테스트케이스'!$N$2:$N$91,"Fail") | J45: 적립금은 결제 금액의 최대 7%까지, 10원 단위로만 사용할 수 있다.
...

Sheet 테스트케이스
A1: TC ID | B1: 대분류 | C1: 중분류 | D1: 요구사항 ID | E1: 설계 근거 | F1: 실행 구분 | G1: 자동화 구분 | H1: 우선순위 | I1: 사전 조건 | J1: 테스트 절차 | K1: 테스트 데이터 | L1: 기대 결과 | M1: 관련 질의 | N1: 결과 | O1: 실측·메모 | P1: 결함 ID | Q1: 수행일 | R1: 수행자 | S1: 스크린샷 | T1: 비고
A2: TC-CART-001 | B2: 장바구니 | C2: 담기 | E2: 추가 검증 | F2: 비결제 | G2: UI | H2: P1 | I2: 로그인 상태, 장바구니 비어 있음 | J2: 1. 상품 상세에서 옵션(색상/사이즈) 선택 2. 수량 1로 [장바구니] 탭 3. 장바구니 진입 | K2: 상품 P1(일반 배송) | L2: 1. 담기 완료 안내가 표시된다 2. 장바구니에 선택한 옵션·수량·판매가가 상세와 동일하게 표시된다 3. 탭 바의 장바구니 뱃지 수가 1 증가한다
A3: TC-CART-002 | B3: 장바구니 | C3: 담기 | E3: 리스크 기반 | F3: 비결제 | G3: UI | H3: P2 | I3: P1 옵션 A가 장바구니에 수량 1로 있음 | J3: 1. 같은 상품의 같은 옵션 A를 수량 2로 다시 담기 2. 장바구니 확인 | K3: 상품 P1 옵션 A | L3: 1. 별도 행이 생기지 않고 수량이 3으로 합산된다(또는 중복 안내 후 선택) 2. 합계 금액이 수량 × 단가와 일치한다 | M3: Q02
A4: TC-CART-003 | B4: 장바구니 | C4: 수량 경계 | E4: 리스크 기반 | F4: 비결제 | G4: UI | H4: P2 | I4: P1이 장바구니에 있음, 옵션 재고 수량 확인(상세의 재고 표기 또는 수량 스텝퍼 상한) | J4: 1. 수량을 1에서 [-]로 0 시도 2. 수량을 상한까지 올린 뒤 [+] 1회 추가 3. 수량 직접 입력 필드가 있으면 0, 음수, 상한+1 입력 | K4: 수량 0 / 상한 / 상한+1 | L4: 1. 0 이하로 내려가지 않는다(버튼 비활성 또는 안내) 2. 상한 초과 시 안내가 표시되고 수량은 상한에 고정된다 3. 합계 금액이 즉시 재계산된다 | M4: Q02
A5: TC-CART-004 | B5: 장바구니 | C5: 삭제 | E5: 추가 검증 | F5: 비결제 | G5: UI | H5: P2 | I5: 서로 다른 상품 3개가 장바구니에 있음 | J5: 1. 1개 상품 선택 삭제 2. 전체 선택 해제 후 [주문하기] 시도 3. 전체 삭제 | K5: 상품 P1, P2, P3 | L5: 1. 삭제한 상품만 사라지고 합계·배송비가 재계산된다 2. 선택 상품이 없으면 주문 버튼이 비활성 또는 안내가 표시된다 3. 빈 장바구니 화면과 추천 영역이 표시되고 뱃지가 0이 된다
A6: TC-CART-005 | B6: 장바구니 | C6: 품절 처리 | D6: REQ-10 | E6: 리스크 기반 | F6: 비결제 | G6: API | H6: P1 | I6: 품절 임박 옵션(재고 1~2)을 장바구니에 담은 뒤, 다른 계정(또는 웹)으로 해당 재고를 선구매해 품절 상태로 만듦 | J6: 1. 앱 장바구니 진입 2. 전체 선택 후 [주문하기] | K6: 품절 옵션 상품 | L6: 1. 품절 상품에 '품절' 표시와 선택 불가 처리가 적용된다 2. 품절 상품은 주문서로 넘어가지 않거나 주문 불가 안내가 표시된다 3. 합계 금액에서 품절 상품이 제외된다 | M6: Q05
A7: TC-CART-006 | B7: 장바구니 | C7: 가격 변동 | E7: 리스크 기반 | F7: 비결제 | G7: API | H7: P2 | I7: 타임세일·브랜드위크 종료 임박 상품을 세일가로 장바구니에 담음 | J7: 1. 세일 종료 후 장바구니 진입 2. 주문서 진입 | K7: 세일 종료 상품 | L7: 1. 장바구니 가격이 현재 판매가로 갱신되고 변동 안내가 표시된다 2. 주문서 금액도 현재 판매가 기준이며 담을 때 가격으로 결제되지 않는다 | M7: Q05
A8: TC-CART-007 | B8: 장바구니 | C8: 브랜드 분리 | D8: REQ-12 | E8: 요구사항 | F8: 비결제 | G8: API | H8: P1 | I8: 브랜드가 다른 상품 2개(각각 배송비 정책 상이)를 담음 | J8: 1. 장바구니 진입 2. 브랜드별 그룹과 배송비 표기 확인 3. 전체 선택 후 합계 확인 | K8: 브랜드 A 상품, 브랜드 B 상품 | L8: 1. 상품이 브랜드별로 그룹화되어 표시된다 2. 배송비가 브랜드별로 표기되고 합계 배송비가 각 배송비의 합과 일치한다 | M8: Q01
A9: TC-CART-008 | B9: 장바구니 | C9: 배송 옵션 | D9: REQ-12 | E9: 요구사항 | F9: 비결제 | G9: UI | H9: P2 | I9: 일반 배송 옵션과 무배당발 옵션이 함께 판매되는 상품 확인(상세의 옵션 목록) | J9: 1. 일반 배송 옵션 담기 2. 무배당발 옵션 담기 3. 장바구니에서 두 행의 배송 표기 확인 | K9: 동일 상품 일반/무배당발 옵션 | L9: 1. 두 옵션이 별도 행으로 표시된다 2. 무배당발 행에는 도착 보장일·무료배송 표기가, 일반 행에는 브랜드 배송비·도착 예정일이 표시된다 | M9: Q01
A10: TC-CART-009 | B10: 장바구니 | C10: 유지 | E10: 리스크 기반 | F10: 비결제 | G10: UI | H10: P2 | I10: 장바구니에 상품 2개, 1개는 선택 해제 상태 | J10: 1. 앱 스위처에서 앱 강제 종료 2. 앱 재실행 후 장바구니 진입 3. 로그아웃 → 로그인 후 장바구니 진입 | K10: 상품 P1(선택), P2(해제) | L10: 1~2. 상품과 수량이 유지된다(선택 상태 유지 여부는 기록) 3. 재로그인 후에도 동일하게 유지된다 | M10: Q08
A11: TC-CART-010 | B11: 장바구니 | C11: 동기화 | E11: 추가 검증 | F11: 비결제 | G11: API | H11: P3 | I11: 같은 계정으로 웹(Safari) 로그인 | J11: 1. 웹에서 상품 P4 담기 2. 앱 장바구니 새로고침(당겨서 새로고침 또는 재진입) 3. 앱에서 P4 삭제 후 웹 새로고침 | K11: 상품 P4 | L11: 1~2. 앱 장바구니에 P4가 나타난다 3. 웹에서도 P4가 사라진다 | M11: Q08
A12: TC-CART-011 | B12: 장바구니 | C12: 쿠폰 미리보기 | D12: REQ-07 | E12: 요구사항 | F12: 비결제 | G12: UI | H12: P2 | I12: 사용 가능 쿠폰 보유, 쿠폰 적용 대상 상품이 장바구니에 있음 | J12: 1. 장바구니에서 쿠폰 적용(또는 '쿠폰 적용가 보기') 2. 할인 후 금액 확인 3. 주문서 진입 | K12: 등급 쿠폰 C1 | L12: 1. 상품 행에 쿠폰 할인가가 표시된다 2. 주문서에 같은 쿠폰이 적용된 상태로 진입되고 할인 금액이 동일하다
A13: TC-ORD-001 | B13: 주문서·금액 | C13: 진입 | E13: 추가 검증 | F13: 비결제 | G13: UI | H13: P1 | I13: 장바구니에 상품 3개, 그중 2개만 선택 | J13: 1. [주문하기] 탭 2. 주문서의 상품 목록·수량·옵션·금액 확인 | K13: 상품 P1, P2 선택 / P3 미선택 | L13: 1. 선택한 2개 상품만 주문서에 표시된다 2. 옵션·수량·판매가가 장바구니와 일치한다
A14: TC-ORD-002 | B14: 주문서·금액 | C14: 금액 정합성 | D14: REQ-04, REQ-08 | E14: 리스크 기반 | F14: 비결제 | G14: API | H14: P1 | I14: 등급 할인 대상 계정, 쿠폰 1장, 적립금 5,000원 이상 보유, 배송비 유료 브랜드 상품 1개 | J14: 1. 주문서에서 쿠폰 적용, 적립금 1,000원 사용 2. 상품 금액·등급 할인·쿠폰 할인·적립금·배송비·최종 결제 금액을 모두 기록 3. 수기로 합산 검증 | K14: 상품 P5(유료 배송), 쿠폰 C1, 적립금 1,000원 | L14: 1. 상품 금액 − 등급 할인 − 쿠폰 할인 − 적립금 + 배송비 = 최종 결제 금액이 1원 단위까지 일치한다 2. 각 항목이 주문서에 개별 표시된다 | M14: Q03
A15: TC-ORD-003 | B15: 주문서·금액 | C15: 등급 할인 | D15: REQ-08 | E15: 요구사항 | F15: 비결제 | G15: API | H15: P1 | I15: 마이 > 등급 혜택 안내에서 현재 등급 할인율 확인 | J15: 1. 할인 적용 가능 상품으로 주문서 진입 2. 등급 할인 금액 확인 | K15: 등급 할인율 r% | L15: 1. 등급 할인 금액이 상품 금액 × r%(원 단위 처리 규칙 기록)와 일치한다 2. 등급 할인 제외 상품은 할인이 적용되지 않고 안내가 표시된다 | M15: Q03
A16: TC-ORD-004 | B16: 주문서·금액 | C16: 품절 차단 | D16: REQ-10 | E16: 리스크 기반 | F16: 비결제 | G16: API | H16: P2 | I16: 재고 1인 옵션으로 주문서까지 진입, 보조 계정 준비 | J16: 1. 주문서를 열어둔 상태에서 보조 계정으로 해당 옵션 구매(품절화) 2. 앱에서 [결제하기] 탭 | K16: 재고 1 옵션, 보조 계정 | L16: 1. 결제가 진행되지 않고 품절 안내가 표시된다 2. 주문·결제가 생성되지 않는다(주문 내역 확인) | M16: Q05
A17: TC-ORD-005 | B17: 주문서·금액 | C17: 적립금 혼합 | D17: REQ-05 | E17: 요구사항 | F17: 비결제 | G17: API | H17: P2 | I17: 적립금 사용 불가 상품 P6과 사용 가능 상품 P1을 함께 선택 | J17: 1. 주문서 진입 2. 적립금 사용 가능 금액(최대) 확인 3. 최대 금액 적용 | K17: 상품 P6(적립금 불가), P1 | L17: 1. P6에 적립금 사용 불가 안내가 표시된다 2. 최대 사용 가능 금액이 P1 기준 7%로 계산되는지 기록한다(Q12 회신 후 확정) | M17: Q12
A18: TC-ORD-006 | B18: 주문서·금액 | C18: 입력 검증 | E18: 추가 검증 | F18: 비결제 | G18: UI | H18: P2 | I18: 배송지 미등록 신규 계정 또는 배송지 전체 삭제 상태 | J18: 1. 배송지 없이 [결제하기] 2. 수령인/연락처 공란으로 [결제하기] 3. 연락처에 문자·10자리 미만 입력 | K18: 공란, '010-12', 'abc' | L18: 1~2. 결제가 진행되지 않고 누락 항목에 오류 메시지와 포커스가 이동한다 3. 형식 오류 안내가 표시된다
A19: TC-ORD-007 | B19: 주문서·금액 | C19: 이탈 복귀 | E19: 추가 검증 | F19: 비결제 | G19: UI | H19: P3 | I19: 주문서에서 쿠폰·적립금 적용, 배송 요청사항 입력 | J19: 1. 뒤로가기로 장바구니 복귀 2. 다시 [주문하기] | K19: 쿠폰 C1, 적립금 1,000원 | L19: 1. 장바구니 상태가 유지된다 2. 쿠폰·적립금·요청사항의 유지/초기화 여부가 일관되고 금액이 재계산된다(현재 동작 기록)
A20: TC-ORD-008 | B20: 주문서·금액 | C20: 선할인 | D20: REQ-06 | E20: 요구사항 | F20: 비결제 | G20: API | H20: P2 | I20: 적립금 선할인 적용 가능 상품 | J20: 1. 주문서에서 적립금 선할인 선택 2. 안내 문구·할인 금액 확인 3. 선할인 해제 | K20: 선할인 가능 상품 | L20: 1. '구매 확정 후 적립금 미지급' 취지의 안내가 표시된다 2. 최종 결제 금액에 선할인이 반영된다 3. 해제 시 원래 금액으로 복원된다 | M20: Q04
A21: TC-ORD-009 | B21: 주문서·금액 | C21: 표기 | E21: 추가 검증 | F21: 비결제 | G21: UI | H21: P3 | I21: 합계가 100만 원 이상이 되도록 상품 구성 | J21: 1. 주문서 금액 영역 확인 | K21: 고가 상품 2개 | L21: 1. 모든 금액에 천 단위 콤마와 '원'이 일관되게 표기된다 2. 할인 항목은 음수(−) 또는 별도 색으로 구분되고 잘림이 없다
A22: TC-ORD-010 | B22: 주문서·금액 | C22: 수량 변경 | E22: 추가 검증 | F22: 비결제 | G22: UI | H22: P3 | I22: 주문서에 수량 2 상품 | J22: 1. 주문서에서 수량 변경 UI 유무 확인 2. 있으면 수량 1로 변경 | K22: 상품 P1 수량 2 | L22: 1. 수량 변경이 가능하면 금액·쿠폰·적립금 한도가 즉시 재계산된다 2. 불가하면 장바구니로 안내된다(현재 동작 기록) | M22: Q03
A23: TC-CPN-001 | B23: 쿠폰 | C23: 적용·해제 | D23: REQ-07 | E23: 요구사항 | F23: 비결제 | G23: API | H23: P1 | I23: 쿠폰 적용 대상 상품 P1, 비대상 상품 P7이 주문서에 있음, 쿠폰 C1 보유 | J23: 1. P1에 쿠폰 C1 적용 2. 금액 확인 3. 쿠폰 해제 | K23: 쿠폰 C1(정률 10%) | L23: 1. P1 행에만 할인이 반영되고 P7 금액은 변동 없다 2. 쿠폰 할인 = P1 금액 × 10%(원 단위 규칙 기록) 3. 해제 시 원복된다
A24: TC-CPN-002 | B24: 쿠폰 | C24: 제외 상품 | D24: REQ-07 | E24: 요구사항 | F24: 비결제 | G24: API | H24: P1 | I24: 쿠폰 사용 제한 상품 P7(상세에 '쿠폰 적용 불가' 표기) 주문서 | J24: 1. P7의 쿠폰 선택 영역 확인 2. 쿠폰 목록 열기 | K24: 상품 P7 | L24: 1. 사용 불가 안내가 표시되거나 선택 영역이 비활성이다 2. 목록에 C1이 '사용 불가'로 표시되거나 노출되지 않는다
A25: TC-CPN-003 | B25: 쿠폰 | C25: 최소 주문 경계 | D25: REQ-07, REQ-15 | E25: 요구사항 | F25: 비결제 | G25: API | H25: P1 | I25: 최소 주문 금액 조건(예: 3만 원 이상)이 있는 쿠폰 C2 보유 | J25: 1. 상품 금액이 조건 − 10원인 구성으로 쿠폰 적용 시도 2. 조건과 동일한 금액으로 적용 3. 조건 + 10원으로 적용 | K25: 쿠폰 C2, 금액 29,990 / 30,000 / 30,010 | L25: 1. 적용되지 않고 조건 미달 안내가 표시된다 2~3. 적용된다(경계 포함 여부 기록)
A26: TC-CPN-004 | B26: 쿠폰 | C26: 최대 할인 경계 | D26: REQ-07 | E26: 요구사항 | F26: 비결제 | G26: API | H26: P2 | I26: 최대 할인 한도(예: 1만 원)가 있는 정률 쿠폰 C3 | J26: 1. 정률 할인이 한도를 초과하는 고가 상품에 적용 2. 한도와 정확히 같은 금액의 상품에 적용 | K26: 쿠폰 C3(20%, 최대 1만 원), 상품 6만 원 / 5만 원 | L26: 1. 할인 금액이 한도 1만 원으로 고정된다 2. 할인 금액이 1만 원이다
A27: TC-CPN-005 | B27: 쿠폰 | C27: 중복 | D27: REQ-07 | E27: 리스크 기반 | F27: 비결제 | G27: API | H27: P2 | I27: 같은 상품에 적용 가능한 등급 쿠폰 C1과 브랜드 쿠폰 C4 보유 | J27: 1. P1에 C1 적용 후 C4 추가 적용 시도 | K27: 쿠폰 C1, C4 | L27: Q04 회신 후 확정. 중복 불가면 교체·거부 안내가 표시되고, 중복 가능하면 두 할인이 모두 반영되며 합산이 정확하다 | M27: Q04
A28: TC-CPN-006 | B28: 쿠폰 | C28: 적립금 병행 | D28: REQ-04, REQ-07 | E28: 요구사항 | F28: 비결제 | G28: API | H28: P1 | I28: 쿠폰 C1, 적립금 5,000원 이상 보유 | J28: 1. 쿠폰 적용 전 적립금 최대 사용 가능 금액 기록 2. 쿠폰 적용 후 최대 사용 가능 금액 기록 3. 적립금 최대 적용 | K28: 쿠폰 C1, 적립금 | L28: 1~2. 7% 한도의 기준 금액이 쿠폰 적용 전/후 중 무엇인지 기록한다(Q03) 3. 쿠폰 할인과 적립금이 모두 반영되고 최종 금액이 계산식과 일치한다 | M28: Q03, Q04
A29: TC-CPN-007 | B29: 쿠폰 | C29: 이동 적용 | D29: REQ-07 | E29: 요구사항 | F29: 비결제 | G29: API | H29: P3 | I29: 쿠폰 적용 가능 상품 P1, P2가 주문서에 있음, 쿠폰 C1 1장 | J29: 1. P1에 C1 적용 2. P2에 C1 적용 시도 | K29: 쿠폰 C1 | L29: 1. P1에 할인 적용 2. C1이 P2로 이동 적용되고 P1 할인이 해제된다(또는 1장 제한 안내), 합계가 재계산된다
A30: TC-CPN-008 | B30: 쿠폰 | C30: 만료 경계 | D30: REQ-07 | E30: 리스크 기반 | F30: 비결제 | G30: API | H30: P2 | I30: 당일 23:59 만료 쿠폰 C5 보유, 23:55에 주문서 진입 후 C5 적용 | J30: 1. 00:01까지 주문서 유지 2. [결제하기] 탭(PG 진입 전 단계에서 중단) | K30: 쿠폰 C5 | L30: 1. 만료 쿠폰이 적용된 채 결제가 진행되지 않고 재확인 안내가 표시된다 2. 금액이 쿠폰 미적용으로 재계산된다 | M30: Q10
A31: TC-CPN-009 | B31: 쿠폰 | C31: 동시 사용 | D31: REQ-07 | E31: 리스크 기반 | F31: 실결제 | G31: API | H31: P2 | I31: 앱과 웹에서 같은 계정으로 각각 주문서에 쿠폰 C1 적용 | J31: 1. 웹에서 C1으로 소액 결제 완료 2. 앱 주문서에서 [결제하기] | K31: 쿠폰 C1, 소액 상품 | L31: 1. 앱에서 이미 사용된 쿠폰으로 결제되지 않고 안내가 표시된다 2. 이중 할인 주문이 생성되지 않는다 ※ 결제된 웹 주문은 즉시 취소 | M31: Q06
A32: TC-CPN-010 | B32: 쿠폰 | C32: 가입 쿠폰 | D32: REQ-15 | E32: 요구사항 | F32: 비결제 | G32: API | H32: P2 | I32: 신규 가입 계정(가입 쿠폰 20% 보유) | J32: 1. 쿠폰함에서 유효기간 확인 2. 9,990원 상품에 적용 시도 3. 10,000원 상품에 적용 | K32: 가입 쿠폰, 상품 9,990 / 10,000원 | L32: 1. 유효기간이 발급일 + 30일로 표시된다 2. 적용되지 않고 조건 안내가 표시된다(1만 원 이상 조건이 쿠폰 조건인지 기록) 3. 20% 할인이 적용된다
A33: TC-PNT-001 | B33: 적립금 | C33: 보유 경계 | D33: REQ-03 | E33: 요구사항 | F33: 비결제 | G33: API | H33: P1 | I33: 적립금 보유 4,990원 계정(M2). 보유액 조정이 어려우면 메인 계정에서 적립금 일부를 사용한 주문을 결제완료 상태로 둔 뒤(잔액 <5,000) 수행하고 취소 | J33: 1. 마이 > 적립금 잔액 확인 2. 주문서에서 적립금 사용 영역 확인 3. 금액 입력 시도 | K33: 보유 4,990원 | L33: 1. 입력이 비활성이고 '5,000원 이상 보유 시 사용 가능' 취지의 안내가 표시된다
A34: TC-PNT-002 | B34: 적립금 | C34: 보유 경계 | D34: REQ-03 | E34: 요구사항 | F34: 비결제 | G34: API | H34: P1 | I34: 적립금 보유 정확히 5,000원 계정(경계), 상품 금액 100,000원 주문서(7% 한도 7,000원 > 보유) | J34: 1. 적립금 10원 입력 2. 5,000원 전액 입력 | K34: 보유 5,000원 | L34: 1. 10원이 적용된다 2. 5,000원 전액이 적용된다(보유 경계 포함)
A35: TC-PNT-003 | B35: 적립금 | C35: 7% 경계 | D35: REQ-04 | E35: 요구사항 | F35: 비결제 | G35: API | H35: P1 | I35: 상품 금액 정확히 100,000원(쿠폰 미적용) 구성, 적립금 1만 원 이상 보유(7% 한도 7,000원 < 보유) | J35: 1. 7,000원 입력 2. 7,010원 입력 3. 6,990원 입력 | K35: 7,000 / 7,010 / 6,990 | L35: 1. 적용된다 2. 7,000원으로 자동 보정되거나 한도 초과 안내가 표시된다(보유액 이내이므로 한도만 작용) 3. 적용된다 | M35: Q03, Q07
A36: TC-PNT-004 | B36: 적립금 | C36: 10원 단위 | D36: REQ-04 | E36: 요구사항 | F36: 비결제 | G36: API | H36: P1 | I36: 적립금 5,000원 이상 보유 | J36: 1. 1,005원 입력 2. 1,001원 입력 3. 1,000원 입력 | K36: 1,005 / 1,001 / 1,000 | L36: 1~2. 10원 단위로 절사되거나 단위 안내와 함께 거부된다(절사/거부 중 현재 동작 기록) 3. 적용된다 | M36: Q03
A37: TC-PNT-005 | B37: 적립금 | C37: 전액 사용 | D37: REQ-04 | E37: 요구사항 | F37: 비결제 | G37: API | H37: P2 | I37: 적립금 보유 5,614원(10원 단위가 아닌 잔액) | J37: 1. 상품 금액 100,000원 주문서에서 [전액 사용] 탭(7% 한도 7,000원 > 보유) 2. 상품 금액 50,000원 주문서에서 [전액 사용] 탭(7% 한도 3,500원 < 보유) | K37: 보유 5,614원, 상품 100,000 / 50,000원 | L37: 1. 보유액을 10원 단위로 절사한 5,610원이 적용된다(5,614원 그대로 적용되면 REQ-04 위반) 2. 한도 3,500원이 적용된다 | M37: Q03
A38: TC-PNT-006 | B38: 적립금 | C38: 사용 불가 상품 | D38: REQ-05 | E38: 요구사항 | F38: 비결제 | G38: API | H38: P1 | I38: 적립금 사용 불가 상품 P6 단독 주문서 | J38: 1. 적립금 영역 확인 | K38: 상품 P6 | L38: 1. 입력이 비활성이고 사용 불가 안내가 표시된다 2. [전액 사용]이 동작하지 않는다
A39: TC-PNT-007 | B39: 적립금 | C39: 제휴 경유 | D39: REQ-05 | E39: 추가 검증 | F39: 비결제 | G39: 수동 | H39: P3 | I39: 외부 광고 링크(검색 광고·제휴 블로그 링크)로 앱 상품 상세를 열어 주문서 진입 | J39: 1. 적립금·선할인 영역 확인 2. 앱을 종료하고 직접 실행 후 같은 상품 주문서 진입 | K39: 제휴 링크 | L39: 1. 제한 안내가 표시되거나 적립금 사용이 비활성이다(현재 동작 기록) 2. 직접 실행 시 정상 사용 가능하다
A40: TC-PNT-008 | B40: 적립금 | C40: 선할인 상호작용 | D40: REQ-06 | E40: 요구사항 | F40: 비결제 | G40: API | H40: P2 | I40: 선할인 가능 상품, 적립금 5,000원 이상 보유 | J40: 1. 적립금 1,000원 사용 후 선할인 선택 2. 선할인 선택 후 적립금 입력 | K40: 적립금 1,000원 | L40: Q04 회신 후 확정. 병행 불가면 한쪽 선택 시 다른 쪽이 해제·비활성되고, 병행 가능하면 두 할인이 모두 반영된다 | M40: Q04
...

Sheet 테스트 데이터
A1: 구분 | B1: ID | C1: 이름 | D1: 조건 | E1: 사용 TC | F1: 준비 완료 | G1: 실제 값(상품명·쿠폰명 등)
A2: 계정 | B2: M1 | C2: 메인 테스트 계정 | D2: 등급 할인 대상(실버 이상), 적립금 1만 원 이상, 등급 쿠폰 보유, 무신사페이 등록, 배송지 2개 | E2: 대부분의 TC
A3: 계정 | B3: M2 | C3: 적립금 미달 계정 | D3: 적립금 4,990원 이하(또는 메인 계정에서 적립금 사용 주문을 결제완료 상태로 둔 뒤 잔액 <5,000 상태 이용) | E3: TC-PNT-001
A4: 계정 | B4: M3 | C4: 신규 가입 계정 | D4: 가입 쿠폰 20%, 가입 적립금 5,000원, 365일 무료배송 | E4: TC-CPN-010, TC-PNT-010, TC-SHP-006
A5: 계정 | B5: M4 | C5: 보조 계정(웹) | D5: 재고 경합·품절 유도용 | E5: TC-CART-005, TC-ORD-004, TC-SEC-006
A6: 상품 | B6: P1 | C6: 일반 배송 상품 | D6: 쿠폰·적립금 사용 가능, 재고 충분. 7% 경계용으로 합계 정확히 100,000원이 되는 구성 1세트 별도 준비 | E6: 기본, TC-PNT-003
A7: 상품 | B7: P2~P4 | C7: 일반 상품 | D7: 서로 다른 브랜드 | E7: 장바구니 복수 상품
A8: 상품 | B8: P5 | C8: 유료 배송 브랜드 상품 | D8: 배송비 3,000원, 도서산간 추가비 있음 | E8: 배송비 TC
A9: 상품 | B9: P6 | C9: 적립금 사용 불가 상품 | D9: 주문서에 적립금 불가 표기 | E9: TC-PNT-006, TC-ORD-005
A10: 상품 | B10: P7 | C10: 쿠폰 사용 제한 상품 | D10: 상세에 쿠폰 적용 불가 표기 | E10: TC-CPN-001/002
A11: 상품 | B11: P8 | C11: 품절 임박 옵션 | D11: 재고 1~2 | E11: 품절·경합 TC
A12: 상품 | B12: P9 | C12: 소액 상품 | D12: 1만 원 이하, 즉시 취소 가능 브랜드 | E12: 실결제 TC
A13: 상품 | B13: P10 | C13: 일반/무배당발 옵션 공존 상품 | E13: TC-CART-008
A14: 쿠폰 | B14: C1 | C14: 등급 쿠폰(월 쿠폰팩, 정률 10% 가정) | D14: 실제 할인율·최소 주문 금액·최대 할인·적용 범위는 쿠폰함에서 확인해 '실제 값'에 기록 | E14: 기본
A15: 쿠폰 | B15: C2 | C15: 최소 주문 금액 쿠폰 | D15: 예: 3만 원 이상 | E15: TC-CPN-003
A16: 쿠폰 | B16: C3 | C16: 최대 할인 한도 쿠폰 | D16: 예: 20%, 최대 1만 원 | E16: TC-CPN-004
A17: 쿠폰 | B17: C4 | C17: 브랜드 쿠폰 | D17: P1 브랜드 대상 | E17: TC-CPN-005
A18: 쿠폰 | B18: C5 | C18: 당일 만료 쿠폰 | D18: 23:59 만료 | E18: TC-CPN-008
A20: ※ 금액·조건은 예시. 실제 쿠폰 조건과 브랜드 배송 정책은 수행 시점에 확인해 '실제 값'에 기록

Sheet 질의사항
A1: ID | B1: 질의 | C1: 영향 | D1: 회신 전 처리 | E1: 영향 TC 수 | F1: 영향 TC | G1: 확인 결과(앱 동작) | H1: 확인일
A2: Q01 | B2: 배송비 산정 규칙: 브랜드별 부과인지, 장바구니 합계 기준 무료배송 조건과 금액, 도서산간 추가 배송비가 반영되는 시점(주문서 진입 시 / 배송지 선택 후) | C2: 금액 정합성, 배송비 TC | D2: 주문서의 배송비 표기와 브랜드별 상품고시정보를 기록해 규칙 역도출 후 판정 | E2: =COUNTIF('테스트케이스'!$M$2:$M$91,"*"&A2&"*") | F2: CART-007, CART-008, SHP-003, SHP-004, SHP-005, SHP-006, CNL-004
A3: Q02 | B3: 장바구니 제한: 담을 수 있는 최대 상품 수, 옵션당 최대 수량, 초과 시 안내 문구 | C3: 장바구니 경계값 TC | D3: 현재 동작(최대값, 안내 문구) 기록 후 판정 | E3: =COUNTIF('테스트케이스'!$M$2:$M$91,"*"&A3&"*") | F3: CART-002, CART-003
A4: Q03 | B4: 할인 적용 순서(등급 할인 → 쿠폰 → 적립금?)와 적립금 7% 한도의 기준 금액(상품 금액 / 쿠폰 적용 후 / 배송비 포함 여부), 10원 미만 절사·반올림 규칙 | C4: 금액 정합성, 적립금 TC | D4: 주문서의 각 항목 금액을 기록해 계산식 역도출 후 판정 | E4: =COUNTIF('테스트케이스'!$M$2:$M$91,"*"&A4&"*") | F4: ORD-002, ORD-003, ORD-010, CPN-006, PNT-003, PNT-004, PNT-005, PNT-009
A5: Q04 | B5: 쿠폰 중복 규칙: 상품당 1장인지, 등급 쿠폰과 브랜드 쿠폰 중복 가능 여부, 쿠폰 할인과 적립금 선할인 병행 가능 여부 | C5: 쿠폰 TC | D5: 현재 동작(적용 가능 조합) 기록 후 판정 | E5: =COUNTIF('테스트케이스'!$M$2:$M$91,"*"&A5&"*") | F5: ORD-008, CPN-005, CPN-006, PNT-008
A6: Q05 | B6: 품절·가격 변동 처리: 장바구니에 담은 뒤 품절·가격 인상된 상품의 표시와 주문 가능 여부, 주문서 진입 후 품절 시 결제가 차단되는 시점 | C6: 장바구니·주문서 TC, 운영 리스크 | D6: 현재 동작(표시 방식, 차단 시점) 기록 후 판정 | E6: =COUNTIF('테스트케이스'!$M$2:$M$91,"*"&A6&"*") | F6: CART-005, CART-006, ORD-004, SEC-006
A7: Q06 | B7: 결제 중단 처리: PG·Apple Pay 화면에서 뒤로가기/앱 종료 시 '결제대기' 주문 생성 여부, 사용한 쿠폰·적립금의 즉시 반환 여부, 재시도 경로 | C7: 결제수단·모바일 TC | D7: 현재 동작(주문 내역 상태, 쿠폰함·적립금 잔액) 기록 후 판정 | E7: =COUNTIF('테스트케이스'!$M$2:$M$91,"*"&A7&"*") | F7: CPN-009, PAY-006, PAY-007, PAY-008, MOB-004, MOB-007, SEC-005
A8: Q07 | B8: '결제 금액'의 정의: 적립금 7% 한도와 결제수단 한도(휴대폰 50만 원, 무신사머니 200만 원)의 기준이 배송비 포함 금액인지, 쿠폰 적용 후 금액인지 | C8: 한도 경계값 TC | D8: 경계 금액 ±10원 구성으로 현재 동작 기록 후 판정 | E8: =COUNTIF('테스트케이스'!$M$2:$M$91,"*"&A8&"*") | F8: PNT-003, SHP-005, PAY-004, PAY-005
A9: Q08 | B9: 장바구니 동기화·유지: 웹과 앱 장바구니 동기화 여부, 로그아웃·재로그인·앱 재설치 시 유지 여부, 비회원 장바구니의 로그인 후 병합 여부 | C9: 장바구니·모바일 TC | D9: 현재 동작 기록 후 판정 | E9: =COUNTIF('테스트케이스'!$M$2:$M$91,"*"&A9&"*") | F9: CART-009, CART-010, MOB-011
A10: Q09 | B10: 즉시 할인 자동 선택 시 다른 결제수단으로 바꾸는 UX(해제 안내 문구 유무)와 해제 후 금액 재계산 | C10: 결제수단 TC | D10: 현재 동작 기록 후 판정 | E10: =COUNTIF('테스트케이스'!$M$2:$M$91,"*"&A10&"*") | F10: PAY-003
A11: Q10 | B11: 가입 적립금 24시간·가입 쿠폰 30일 만료 경계: 주문서를 열어둔 채 만료 시각이 지나면 적용된 혜택이 어떻게 처리되는지 | C11: 신규 혜택 TC, 금액 정합성 | D11: 만료 직후 결제 시도 시 현재 동작 기록 후 판정 | E11: =COUNTIF('테스트케이스'!$M$2:$M$91,"*"&A11&"*") | F11: CPN-008, PNT-010
A12: Q11 | B12: 상품준비중 취소 요청이 거절될 때의 알림(알림톡·앱 푸시)과 앱 내 상태 표시, 요청 철회 후 재요청 불가 처리 | C12: 주문 취소 TC | D12: 현재 동작 기록 후 판정 | E12: =COUNTIF('테스트케이스'!$M$2:$M$91,"*"&A12&"*") | F12: CNL-005
A13: Q12 | B13: 적립금 사용 불가 상품과 가능 상품을 함께 주문할 때 7% 한도의 기준 금액(가능 상품 금액만인지)과 주문서 표시 | C13: 적립금 TC | D13: 현재 동작(한도 금액, 안내) 기록 후 판정 | E13: =COUNTIF('테스트케이스'!$M$2:$M$91,"*"&A13&"*") | F13: ORD-005
A15: ※ 영향 TC 목록은 2026-10-25 설계 시점 기준. TC의 '관련 질의' 열을 바꾸면 '영향 TC 수'만 자동 갱신됨

Sheet 모바일 체크리스트
A1: 관점 | B1: 확인 항목 | C1: 연결 TC | D1: 비고
A2: 앱 생명주기 | B2: 백그라운드/포그라운드 전환, 장시간 대기 후 세션 만료, 강제 종료 후 복구 | C2: TC-MOB-001, TC-MOB-007, TC-CART-009
A3: 네트워크 | B3: 오프라인, Wi-Fi↔셀룰러 전환, 저속망, 요청 중복 전송 | C3: TC-MOB-002, TC-MOB-003
A4: 인터럽트 | B4: 전화 수신, 알림 배너, 알람, 시리 호출 | C4: TC-MOB-004
A5: 진입 경로 | B5: 푸시 딥링크, 유니버설 링크, 제휴 링크(바로 접속 OFF) | C5: TC-MOB-005, TC-MOB-006, TC-PNT-007
A6: OS 통합 | B6: Apple Pay 시트, 앱 스위처 스냅샷, 스와이프 백 제스처, 키보드 | C6: TC-PAY-006, TC-SEC-004, TC-MOB-008, TC-MOB-009
A7: 권한 | B7: 알림 권한 거부 시 대체 경로 | C7: TC-MOB-010
A8: 설치·업데이트 | B8: 업데이트 후 로그인·장바구니 유지 | C8: TC-MOB-011
A9: 기기·OS 매트릭스 | B9: iOS 최신/직전, 소형/대형 화면 | C9: TC-CMP-001, TC-CMP-002
A10: 접근성·표시 | B10: 다이나믹 타입, VoiceOver, 다크 모드, 시스템 언어 | C10: TC-CMP-003 ~ TC-CMP-006
A11: 데이터 동기화 | B11: 웹↔앱 장바구니, 다중 기기 동시 사용 | C11: TC-CART-010, TC-CPN-009, TC-SEC-006
A13: ※ 앱 테스트 학습용 관점 목록. 각 관점이 최소 1개 TC로 연결되도록 설계

Sheet 결함 리포트
A1: 결함 ID | B1: TC ID | C1: 제목 | D1: 심각도 | E1: 우선순위 | F1: 환경(기기/iOS/앱 버전) | G1: 재현 절차 | H1: 기대 결과 | I1: 실제 결과 | J1: 재현율 | K1: 첨부 | L1: 상태 | M1: 등록일 | N1: 비고
A2: DEF-000 | B2: TC-PNT-004 | C2: (예시) 적립금 1,005원 입력 시 단위 안내 없이 1,005원 그대로 적용됨 | D2: S2 | E2: P1 | F2: iPhone 15 / iOS 18.x / 앱 x.y.z | G2: 1. 주문서 적립금 입력 1,005원 2. 적용 버튼 탭 3. 최종 결제 금액 확인 | H2: 10원 단위 절사(1,000원) 또는 단위 안내 후 거부 | I2: 1,005원이 그대로 차감되어 최종 금액이 5원 단위로 표시 | J2: 3/3 | K2: def-000-1.png | L2: 신규 | M2: 2026-10-26 | N2: 예시 행 — 실제 결함 등록 시 삭제
A25: 심각도 기준
A26: S1 | B26: 결제 금액 오류, 중복 결제, 주문·데이터 유실, 크래시로 결제 불가
A27: S2 | B27: 주요 기능(쿠폰·적립금·취소) 동작 불가 또는 정책과 다른 금액 처리
A28: S3 | B28: 안내 문구·UI 오류, 우회 가능한 기능 이상
A29: S4 | B29: 개선 제안, 사소한 표기
